Workbook

Sheet 표지
N4: 신용회복위원회 통합 AI 플랫폼 구축
A7: 요구사항정의서 - 기능·비기능(최종본)
N9: CCRS-REQ-02-01(요구사항정의서-기능, 비기능)
N10: 2026.08.20
N11: v.0.99
A19: ㈜제논

Sheet 재개정이력
A1: 제개정 이력
A3: 번호 | B3: 버전 | C3: 작성일 | D3: 변경내용 | I3: 작성자 | J3: 검토/승인자
A4: 1 | B4: v.0.5 | C4: 2026.05.12 | D4: 최초 작성 | I4: 권성식 | J4: -
A5: 2 | B5: v.0.6 | C5: 2026.05.13 | D5: 요구사항별 수행방안 작성 및 보완 | I5: 권성식 | J5: -
A6: 3 | B6: v.0.7 | C6: 2026.05.14 | D6: 요구사항정의서 서식 변경 | I6: 권성식 | J6: -
A7: 4 | B7: v.0.8 | C7: 2026.05.18 | D7: 요구사항정의서 취합, 내용 수정 및 보완 | I7: 권성식 | J7: -
A8: 5 | B8: v.0.9 | C8: 2026.07.21 | D8: 최종 검토 반영: 수행사 표기 및 담당 역할 정정, 최종본 확정 | I8: 김현근 | J8: 권성식
A9: 6 | B9: v.0.99 | C9: 2026.08.20 | D9: 위원회 검토 의견에 따른 수행사 의견 반영 | I9: 김현근 | J9: 권성식
A10: 7 | B10: v.0.999 | C10: 2026.08.24 | D10: 3차 위원회 검토 의견에 따른 수행사 의견 반영 | I10: 김현근 | J10: 권성식

Sheet 요구사항 요약
A1: 요구사항(기능, 비기능) 총괄 현황
M2: 46254
A3: 구분 | C3: 요구사항범위 | E3: 분석 | F3: 담당 수행사 | G3: 설계 | J3: 구현/테스트/전개/종료 | M3: 비고
C4: 제안요청서 | D4: 요구사항명 | E4: 요구사항수 | G4: 기본 | H4: 추가 | I4: 합계 | J4: 기본 | K4: 추가 | L4: 합계
A5: 기능 | B5: 기능 | C5: SFR-001 | D5: AI 통합 포털 기능 구현 | E5: =COUNTIF('기능'!E6:E451,"sfr-001*") -> 17 | F5: 제논
C6: SFR-002 | D6: 문서 파싱·청킹 및 전처리 기능 | E6: =COUNTIF('기능'!E7:E452,"sfr-002*") -> 28 | F6: 제논
C7: SFR-003 | D7: 지식화 파이프라인·분류·시점관리 및 벡터 인덱스 | E7: =COUNTIF('기능'!E8:E453,"sfr-003*") -> 37 | F7: 제논
C8: SFR-004 | D8: 검색 최적화 및 질의 처리 기능 | E8: =COUNTIF('기능'!E9:E454,"sfr-004*") -> 21 | F8: 제논
C9: SFR-005 | D9: 컨텍스트 구성 및 답변 신뢰성·출처 검증 기능 | E9: =COUNTIF('기능'!E10:E455,"sfr-005*") -> 13 | F9: 제논
C10: SFR-006 | D10: 표준 서식 템플릿 매핑 및 HWPX 변환 기능 | E10: =COUNTIF('기능'!E11:E456,"sfr-006*") -> 8 | F10: 제논
C11: SFR-007 | D11: 대화 관리 및 프롬프트 라이브러리 기능 | E11: =COUNTIF('기능'!E12:E457,"sfr-007*") -> 17 | F11: 제논
C12: SFR-008 | D12: 피드백 기반 품질 개선 및 골든셋 평가 기능 | E12: =COUNTIF('기능'!E13:E458,"sfr-008*") -> 19 | F12: 제논
C13: SFR-009 | D13: RAG 품질 및 성능 통합 모니터링 대시보드 | E13: =COUNTIF('기능'!E14:E459,"sfr-009*") -> 14 | F13: 제논
C14: SFR-010 | D14: Web 기반 UI 샌드박스 및 정책 변경관리 기능 | E14: =COUNTIF('기능'!E15:E460,"sfr-010*") -> 10 | F14: 제논
C15: SFR-011 | D15: 보안 가드레일·PII 관리 및 감사 로그 기능 | E15: =COUNTIF('기능'!E16:E461,"sfr-011*") -> 37 | F15: 제논
C16: SFR-012 | D16: 플랫폼 자원·LLM 모델 통합 관리 기능 | E16: =COUNTIF('기능'!E17:E462,"sfr-012*") -> 24 | F16: 제논
C17: SFR-013 | D17: AI 사전 구축 서비스(Agent) 통합 운영 기능 | E17: =COUNTIF('기능'!E18:E463,"sfr-013*") -> 16 | F17: 제논
C18: SFR-014 | D18: 콜센터 상담 어시스턴트 구축 | E18: =COUNTIF('기능'!E19:E464,"sfr-014*") -> 21 | F18: 위고
C19: SFR-015 | D19: Agent 상담지식 | E19: =COUNTIF('기능'!E20:E465,"sfr-015*") -> 9 | F19: 제논
C20: SFR-016 | D20: Agent 데이터길잡이 | E20: =COUNTIF('기능'!E21:E466,"sfr-016*") -> 15 | F20: 제논
C21: SFR-017 | D21: STT 데이터 기반 표준 상담 스크립트 개발 | E21: =COUNTIF('기능'!E22:E467,"sfr-017*") -> 10 | F21: 위고 PWC 제논 | M21: 실시간 추천은 SFR-014로 분리. STT 이력 분석→질문 단위 Q&A 스크립트 설계·검증·승인 체계로 정의
C22: SFR-018 | D22: Agent 문서작성 지원 | E22: =COUNTIF('기능'!E23:E468,"sfr-018*") -> 13 | F22: 제논
C23: SFR-019 | D23: Agent 민원처리 지원 | E23: =COUNTIF('기능'!E24:E469,"sfr-019*") -> 9 | F23: 제논
C24: SFR-020 | D24: Agent 업무담당자 검색 | E24: =COUNTIF('기능'!E25:E470,"sfr-020*") -> 8 | F24: 제논
C25: SFR-021 | D25: Agent 협약기관 검색 | E25: =COUNTIF('기능'!E26:E471,"sfr-021*") -> 7 | F25: 제논
C26: SFR-022 | D26: Agent 채권양수도 추론 | E26: =COUNTIF('기능'!E27:E472,"sfr-022*") -> 6 | F26: 제논
C27: SFR-023 | D27: Agent 사내규정 검색 | E27: =COUNTIF('기능'!E28:E473,"sfr-023*") -> 10 | F27: 제논 | M27: 사내규정 검색 + 국가법령정보 공동활용 OPEN API 8종(목록/본문) 연계, As-of-Date·원문 출처 표시
C28: SFR-024 | D28: 차기 변제금 납입 가능성 예측 모델 구축 | E28: =COUNTIF('기능'!E29:E474,"sfr-024*") -> 8 | F28: PWC/제논
C29: SFR-025 | D29: 최적 채무조정제도 진단 추천 모델 구축 | E29: =COUNTIF('기능'!E30:E475,"sfr-025*") -> 8 | F29: PWC/제논
C30: SFR-026 | D30: 소액대출 이용자 연체 예측 모델 구축 | E30: =COUNTIF('기능'!E31:E476,"sfr-026*") -> 8 | F30: PWC/제논
C31: SFR-027 | D31: 예측모델 관리 대시보드 | E31: =COUNTIF('기능'!E32:E477,"sfr-027*") -> 15 | F31: 제논
C32: SFR-028 | D32: 자동화 및 대응 | E32: =COUNTIF('기능'!E33:E478,"sfr-028*") -> 9 | F32: 제논
C33: SFR-029 | D33: 실험 및 신규 모델 개발 | E33: =COUNTIF('기능'!E34:E479,"sfr-029*") -> 16 | F33: 제논
C34: SFR-030 | D34: 시각화 및 실무연계, 노코드 기반 공통 운영 | E34: =COUNTIF('기능'!E34:E479,"sfr-030*") -> 8 | F34: 제논
C35: SFR-031 | E35: =COUNTIF('기능'!E34:E479,"sfr-031*") -> 1 | F35: 제논 | M35: 기술협상
C36: SFR-032 | E36: =COUNTIF('기능'!E34:E479,"sfr-032*") -> 1 | F36: 제논 | M36: 기술협상
C37: SFR-033 | E37: =COUNTIF('기능'!E34:E479,"sfr-033*") -> 1 | F37: 제논 | M37: 기술협상
C38: SFR-034 | E38: =COUNTIF('기능'!E34:E479,"sfr-034*") -> 1 | F38: 제논 | M38: 기술협상
C39: SFR-035 | E39: =COUNTIF('기능'!E35:E480,"sfr-035*") -> 1 | F39: 제논 | M39: 기술협상
A40: 기능합계 | E40: =SUM(E5:E39) -> 446 | G40: 0 | H40: 0 | I40: 0
...

Sheet 기능
A1: 요구사항정의서-기능
A2: 사업명 | D2: 신용회복위원회 통합 AI 플랫폼 구축 사업 | H2: 업무 구분 | K2: 기능 요구사항 | P2: 작성자 | S2: 김현근
A3: 단계 | D3: 요구분석, 설계, 구현, 테스트, 전개 | H3: 작성일자 | K3: 2026.08.24 | P3: 버전 | S3: v.0.999
J4: Q
A5: 요구사항 분류 | B5: 요구사항 고유번호 | C5: 요구사항 명 | D5: 정의 | E5: 상세요구사항ID | F5: 상세요구사항명 | G5: 상세요구사항 설명 | H5: 요구사항 출처 | I5: 담당 수행사 | J5: 제약사항 및 처리(수행)방안 | K5: 위원회 검토 의견 | L5: 산출정보(RFP 기준) | M5: 산출물(방법론 테일러링 결과서) | N5: 요구사항 상태 | O5: 중요도 | P5: 담당자 | Q5: 완료여부 | R5: 수행사 수용 여부 | S5: 위원회 수용 여부 | T5: 비고(변경처리내역 등)
A6: 기능 요구사항 | B6: SFR-001 | C6: AI 통합 포털 기능 구현 | D6: [포털] AI 통합 포털, 인증·세션, 알림·공지, 법규 준수, 폐쇄망 운영 기능 제공 | E6: SFR-001-01-01 | F6: 단일 포털 진입점 및 메뉴 통합 | G6: 시스템은 AI 서비스, MLOps 운영, 플랫폼 관리 기능 전체를 단일 웹 UI에서 접근할 수 있는 통합 포털 제공하여야 한다. | H6: RFP | I6: 제논 | J6: 플랫폼 통합 포털, 메뉴 통합, IAM 권한 기능 적용 | L6: · 화면설계서 · 사용자 매뉴얼 · 관리자 매뉴얼 | Q6: 완료 | R6: 수용 | S6: 수용 | T6: 46232
E7: SFR-001-01-02 | G7: 시스템은 (통합 메뉴) 서비스 허브, 모니터링, 정책변경, 보안, 감사/로그 등 하위 메뉴 통합 제공하여야 한다. | H7: RFP | I7: 제논 | J7: [Before] 서비스 허브는 AI 통합 포털 서비스로 구현하고, 모니터링, 정책 변경, 보안, 감사/로그는 GenOS 플랫폼 기능 적용 [After] 서비스 허브는 어드바이저, 어시스턴트 서비스로 구현하고, 모니터링, 정책 변경, 보안 감사/로그는 GenOS 플랫폼(AI 포탈) 기능 적용 | K7: J열은 서비스 허브(AI 통합 포털)와 관리 기능(GenOS 플랫폼)을 상이한 시스템으로 기재하고 있어, SFR-001-01-01의 '단일 웹 UI 접근' 요건 충족 여부가 불명확함. 사용자가 두 시스템을 별도 화면·별도 주소로 이용하게 되는지, 단일 포털 내 메뉴로 통합되는지 화면 설계서로 확인 요망. | Q7: 완료 | R7: 수용 | S7: 수용 | T7: 46255
E8: SFR-001-01-03 | G8: (권한별 접근) 사용자 권한(운영자/권한을 부여받은 사용자/일반 사용자)에 따라 접근 가능 기능 영역 구분 | H8: RFP | I8: 제논 | J8: 플랫폼 IAM 기능과 SSO 연동을 통해 기능 구현 | Q8: 완료 | R8: 수용 | S8: 수용 | T8: 46232
E9: SFR-001-01-04 | G9: (단일 세션) 포털 내 모든 영역 간 전환 시 재인증 없이 단일 세션 유지 | H9: RFP | I9: 제논 | J9: [Before] JSON Web Token으로 구현 | K9: JWT 적용만으로는 SFR-001-01-02의 이원 구성(AI 통합 포털 ↔ GenOS 플랫폼) 간 재인증 없는 전환이 보장되는지 확인 어려울 것으로 예상. 두 영역 간 세션 연계 방식, 토큰 유효기간·갱신 정책, 로그아웃 시 토큰 무효화 처리방안에 대해 추가 수행방안 요청 | Q9: 완료 | R9: 수용 | S9: 수용 | T9: 46255
E10: SFR-001-02-01 | F10: 사용자 인증 및 세션 관리 | G10: 시스템은 로그인·로그아웃·비밀번호 변경 등 사용자 인증 기능 및 세션 관리 기능 제공하여야 한다. | H10: RFP | I10: 제논 | J10: - 반디의 로그인 화면 이용 - 로그아웃 시 실제로 업무 시스템이 로그아웃 되는 것이 아닌 창 닫기는 것으로 정의 - 비밀번호 변경 기능은 제공하지 않음 | Q10: 완료 | R10: 수용 | S10: 수용 | T10: 46232
E11: SFR-001-02-02 | G11: (SSO 연동) SSO 연동을 지원하며, 연동 방식 및 대상 시스템은 위원회와 협의 | H11: RFP | I11: 제논 | J11: 신복위 SSO 정책에 따라 적용하며 대상 시스템은 위원회 협의에 따라 적용 | Q11: 완료 | R11: 수용 | S11: 수용 | T11: 46232
E12: SFR-001-02-03 | G12: (권한 관리) 역할 기반 접근 제어(RBAC) 적용, 기존 위원회 인사체계 준용 | H12: RFP | I12: 제논 | J12: 신복위 인사체계를 준용하여 RBAC 기반 플랫폼 IAM 기능 적용 | Q12: 완료 | R12: 수용 | S12: 수용 | T12: 46232
E13: SFR-001-03-01 | F13: 사용자 알림·공지 및 매뉴얼 | G13: 시스템은 사용자별 알림 표시, 공지사항 조회·팝업, 화면별 매뉴얼 페이지 이동 기능 제공하여야 한다. | H13: RFP | I13: 제논 | J13: 플랫폼의 알림, 공지사항 기능 적용, 화면별 매뉴얼 페이지 이동 기능 구현 상기 매뉴얼 페이지 이동 기능 구현을 위해 매뉴얼은 기본적으로 gitbook.io 형태로 제공 및 pdf export 기능 제공 [Advisor] - 공시사항 및 공지 팝업 기능 구현 - 별도의 사용자 알림 미제공, 가드레일 위반 시 대화 응답(disclaimer)으로 경고 | Q13: 완료 | R13: 수용 | S13: 수용 | T13: 46232
E14: SFR-001-04-01 | F14: AI 서비스 직접 이용 | G14: 포털 화면 내에서 AI 서비스를 직접 이용할 수 있으며, 서비스 간 전환 시 대화 세션 유지 | H14: RFP | I14: 제논 | J14: 포털 화면 내에서 AI 서비스 엔드포인트 접근 기능 적용, 서비스 간 전환 시 대화 세션 유지 기능 구현 | Q14: 완료 | R14: 수용 | S14: 수용 | T14: 46232
E15: SFR-001-05-01 | F15: MLOps 및 관리 기능 접근 ※ 구체적인 UI 구성 방식은 사업자 제안 후 위원회와 협의하여 확정 | G15: 운영자·관리자가 포털 내에서 모델 서빙, 학습 관리, 데이터 관리, 자원 할당 등 MLOps 운영 기능에 접근 가능 | H15: RFP | I15: 제논 | J15: [Before] 포털내에서 운영자, 관리자가 모델 서빙, 학습 관리, 데이터 관리, 자원 할당 등 MLOps 운영 기능에 접근 가능하도록 기능 구현 (구체적인 UI 구성 방식은 위원회와 협의하여 확정) [After] 포털내에서 운영자, 관리자가 모델 서빙, 학습 관리, 데이터 관리, 자원 할당 등 MLOps 운영 기능에 접근 가능하도록 기능 구현 시안 A, B안 제공 | K15: UI 설계 전 타사 사례 및 참고할만한 시안을 먼저 제공 요청 | Q15: 완료 | R15: 수용 | S15: 수용 | T15: 46255
E16: SFR-001-05-02 | G16: 시스템은 (영역 구분) 생성형 AI 서비스 영역과 MLOps 운영 영역을 메뉴 또는 탭 구조로 구분 제공하여야 한다. | H16: RFP | I16: 제논 | J16: 플랫폼에 구현된 서비스를 활용하여 생성형AI 서비스와 MLOps서비스 영역을 메뉴로 구분하여 적용 | Q16: 완료 | R16: 수용 | S16: 수용 | T16: 46232
E17: SFR-001-06-01 | F17: 법규 준수 및 운영 조건 | G17: (법령 준수) 「인공지능 발전과 신뢰 기반 조성 등에 관한 기본법」 및 동법 시행령을 준수하여야 한다. | H17: RFP | I17: 제논 | J17: [Before] 해당 법령 및 가이드라인을 준수하여 개발 (추가 논의 필요한 사항은 별도 위원회와 협의하여 적용) [After] 해당 법령과 「개인정보 보호법」 및 동법 시행령, 「신용정보의 이용 및 보호에 관한 법률」 및 동법 시행령 및 가이드라인을 준수하여 개발 (추가 논의 필요한 사항은 별도 위원회와 협의하여 적용) | K17: 준수 대상은 인공지능기본법 외 「개인정보 보호법」 및 동법 시행령, 「신용정보의 이용 및 보호에 관한 법률」 및 동법 시행령을 포함 | Q17: 완료 | R17: 수용 | S17: 수용 | T17: 46255
E18: SFR-001-06-02 | G18: (가이드라인 반영) 「금융분야 생성형 AI 활용 지원방안」(금융위원회) 및 「금융 AI 7대 원칙」을 참조하여 시스템 설계·운영에 반영하여야 한다. | H18: RFP | I18: 제논 | J18: [Before] 「금융분야 생성형 AI 활용 지원방안」(금융위원회) 및 「금융 AI 7대 원칙」을 참조하여 시스템 설계·운영에 반영 (추가 논의 필요한 사항은 별도 위원회와 협의하여 적용) [After] 「금융분야 생성형 AI 활용 지원방안」(금융위원회), 과기정통부·개인정보보호위원회·금융감독원·금융위원회·국가정보원 가이드라인 및 「금융 AI 7대 원칙」을 참조하여 시스템 설계·운영에 반영 (추가 논의 필요한 사항은 별도 위원회와 협의하여 적용) | K18: 다음 가이드라인을 시스템 설계 및 운영에 반영 - [과학기술정보통신부] 인공지능기본법 하위 가이드라인(고영향 인공지능 판단 가이드라인, 고영향 인공지능 사업자 책무 가이드라인, 인공지능 영향평가 가이드라인, 인공지능 투명성 확보 가이드라인, 인공지능 안전성 확보 가이드라인 - [개인정보보호위원회] 자동화된 결정에 대한 정보주체의 권리 안내서, 생성형 인공지능(AI) 개발 및 활용을 위한 처리 안내서, 가명정보 처리 가이드라인, 개인정보 영향평가 수행안내서, 공공 AX 프라이버시 보호 안내성(안) - [금융감독원] 금융분야 AI 위험관리 프레임워크(AI RMF) - [금융위원회] 금융분유야 가명, 익명처리 안내서 - [국가정보원] 국가, 공공기관 AI 보안 가이드북 | Q18: 완료 | R18: 수용 | S18: 수용 | T18: 46255
E19: SFR-001-06-03 | G19: (변경 대응) 관련 법률·가이드라인의 제·개정 시 위원회와 협의하여 운영에 반영할 수 있는 절차를 수립하여야 한다. | H19: RFP | I19: 제논 | J19: [Before] 관련 법률·가이드라인의 제·개정 시 위원회와 협의하여 시스템 적용 범위를 도출하고, 사업기간 내 적용 가능한 범위내에서 기능 구현 [After] 관련 법률·가이드라인의 제·개정 시 위원회와 협의하여 시스템 적용 범위를 도출하고, 사업기간 내 적용 가능한 범위내에서 기능 구현 사업기간 중에는 수행사 PM·보안담당이 법령 및 가이드라인 제·개정을 정기 모니터링하고 영향분석·위원회 승인 후 반영 운영 이관 시에는 모니터링 대상, 담당부서, 검토·승인·반영 절차와 이력관리 방법을 운영 Runbook으로 인계 | K19: 제/개정 모니터링 대상은 K17의 법령 전체 및 K18의 가이드라인·안내서 전체. 다만 J열의 '사업기간 내'와 관련하여, 사업기간 중 모니터링 주체와 운영 이관 후 절차(위원회 인계 범위)를 구분하여 명시 요망. | Q19: 완료 | R19: 수용 | S19: 수용 | T19: 46255
E20: SFR-001-07-01 | F20: 폐쇄망 운영 전제 ※ 망 구성(내부망/대외망/DMZ) 세부사항은 위원회와 협의하여 확정 | G20: 모든 컴포넌트가 외부 인터넷 완전 차단된 폐쇄망 환경에서 100% 독립 작동 | H20: RFP | I20: 제논 | J20: 온프레미스 환경에서 100% 독립 작동할 수 있도록 기능 구현 (플랫폼은 온프레미스 환경에서 100% 독립 작동 가능함) (망 구성(내부망/대외망/DMZ) 세부사항은 위원회와 협의하여 확정) | Q20: 완료 | R20: 수용 | S20: 수용 | T20: 46232
E21: SFR-001-07-02 | G21: 시스템은 (외부 연동) 외부 데이터 수집은 대외망에서 수행, 내부망 반입 시 승인·검증·무해화 절차 적용하여야 한다. | H21: RFP | I21: 제논 | J21: [Before] 외부데이터 수집은 위원회로부터 승인된 방식으로 수집하며, 내부망 반입 필요 시 위원회 승인, 검증, 무해화 절차를 통해 반입 [After] 외부데이터 수집은 위원회로부터 승인된 방식으로 수집하며, 내부망 반입 필요 시 위원회 승인, 검증, 무해화 절차를 통해 반입 (위원회 기존 보안체계를 이용) | K21: J열의 '위원회 승인, 검증, 무해화 절차'가 위원회 기존 보안체계를 이용한다는 의미인지, 본 사업에서 해당 절차·수단을 구축한다는 의미인지 불명확함. | Q21: 완료 | R21: 수용 | S21: 수용 | T21: 46255
E22: SFR-001-07-03 | G22: (모델 반입) 오픈소스 LLM 등 외부 패키지는 오프라인 방식 반입, 보안 검증 필수 | H22: RFP | I22: 제논 | J22: [Before] LLM, 임베딩 모델은 huggingface safety checker로 검증된 모델만 반입하고, 패키지는 라이브러리 취약점 점검 후 반입 [After] LLM, 임베딩 모델은 huggingface safety checker로 검증된 모델만 반입하고, 패키지는 라이브러리 취약점 점검 후 반입 외부 데이터 반입은 위원회 기존 보안 반입·승인·검증·무해화 절차를 준용 본 사업에서는 해당 절차를 준수하기 위한 반입 체크리스트, 파일 검증·이력 기록 및 연계 기능을 제공하며, 추가 보안수단이 필요한 경우 별도 협의하여 확정 | K22: 허깅페이스의 'safety checker'은 통상 생성 이미지의 유해 콘텐츠 필터 로 알고 있음. 이는 보안 취약점 검사와 다른 개념으로 이해. 폐쇄망 반입에 필요한 것은 모델 파일에 악성코드가 숨어 있는 지 확인하는 검사와 파일 무결성 검증이므로 수행방안에 대한 보완 필요. 폐쇄망에서는 허깅페이스 접속이 불가하므로, '검증'을 어디서 언제 어떻게 수행할지에 대한 수행 방안 제시 필요 | Q22: 완료 | R22: 수용 | S22: 수용 | T22: 46255
A23: 기능 요구사항 | B23: SFR-002 | C23: 문서 파싱·청킹 및 전처리 기능 | D23: [데이터 수집·전처리] 비정형 문서 파싱·정규화, HWP 변환, 청킹 전략, 검수·교정, 지식 등록·승인 | E23: SFR-002-01-01 | F23: 통합 데이터 처리 및 정규화 | G23: 시스템은 다양한 형식의 비정형 문서를 자동으로 파싱하고 구조화된 형태로 정규화하는 기능 제공하여야 한다. | H23: RFP | I23: 제논 | J23: HWP, HWPX, PDF, DOCX, XLSX, PPTX 등 주요 문서 구조화 및 Semantic Chunking 기능 적용 (단, HWP는 PDF로 변환하여 적용) | L23: · 비정형 문서 구조화 내역서 · 데이터 흐름도 및 파이프라인 설계서 · 테이블 정의서 | Q23: 완료 | R23: 수용 | S23: 수용 | T23: 46232
E24: SFR-002-01-02 | G24: 시스템은 (지원 포맷) HWP, HWPX, PDF, DOCX, XLSX, PPTX 등 주요 문서 형식 지원하여야 한다. | H24: RFP | I24: 제논 | J24: HWP, HWPX, PDF, DOCX, XLSX, PPTX 등 주요 문서 형식 지원 (단, HWP는 PDF로 변환하여 적용) | Q24: 완료 | R24: 수용 | S24: 수용 | T24: 46232
E25: SFR-002-01-03 | G25: 시스템은 (구성요소 추출) 텍스트·표·이미지를 요소별로 분리·추출하며, 표 파싱 시 행·열 구조 보존하여야 한다. | H25: RFP | I25: 제논 | J25: 지능형 전처리기(Doc Parser) 기능 적용하여 구성요소 추출 및 구조 보존 적용 | Q25: 완료 | R25: 수용 | S25: 수용 | T25: 46232
E26: SFR-002-01-04 | G26: (OCR 처리) 스캔 PDF, 문서 내 삽입 이미지 등에 VLM/OCR을 적용 하여 텍스트 추출 | H26: RFP | I26: 제논 | J26: [Before] Image Description 기능을 통해 스캔 PDF, 문서 내 삽입 이미지 등에서 텍스트 추출 [After] 스캔 PDF·이미지의 문자 원문 추출은 VLM 수행하고, 도표·그림의 의미 설명은 Image Description을 보조적으로 적용하여 기능을 구분 위원회 샘플 문서로 본문·표·특수문자 인식 품질을 선행 검증하고, 기준 미달 문서는 수동 검수 대상으로 분류 | K26: G열은 'VLM/OCR 적용'을 명시하고 있으나 J열의 Image Description은 이미지 설명문 생성 기능으로 문자 인식(OCR)과 상이함. 스캔 PDF의 본문 텍스트를 원문 그대로 추출하는 기능인지 확인 요청 | Q26: 완료 | R26: 수용 | S26: 수용 | T26: 46255
E27: SFR-002-01-05 | G27: 시스템은 (노이즈 제거) 불필요한 머리글·바닥글 제거, 연속 공백·개행 통일, 특수 기호 보존 등 정규화 처리하여야 한다. | H27: RFP | I27: 제논 | J27: 지능형 전처리기 기능을 통해 Item 유형 파악 및 노이즈 제거 | Q27: 완료 | R27: 수용 | S27: 수용 | T27: 46232
E28: SFR-002-01-06 | G28: (비정형 문서 구조화) 비정형 문서를 논리적 단위(장/절/조항/항목 등)로 구조화하는 기능 제공. 문서 내 표·그래프·사진 등 복합 객체를 자동 식별·분류하며, 표는 셀 단위 인식 및 행·열 구분 가능. | H28: RFP | I28: 제논 | J28: 지능형 전처리기 기능을 통해 구조화, 복합 객체 자동 식별·분류, 표는 셀 단위 인식 및 행·열 구분 | Q28: 완료 | R28: 수용 | S28: 수용 | T28: 46232
E29: SFR-002-02-01 | F29: HWP 표준 변환 파이프라인 ※ HWP 파싱에 상용 솔루션 도입 시 해당 비용을 제안가에 포함. 오픈소스 활용 시 BMT 결과 제출 필요 | G29: 시스템은 HWP 원본의 파싱 품질 확보를 위한 HWP → PDF 변환 파이프라인 제공하여야 한다. | H29: RFP | I29: 제논 | J29: [Before] Doc Parser v2.2.0 이상에서 기능 제공 (HWP 파싱에 사용하는 솔루션은 수행사 솔루션으로 제안가에 포함되어 있으머 따라서, BMT는 해당사항 없음) [After] Doc Parser v2.2.0 이상에서 기능 제공 대량 적재 전 위원회 제공 HWPX 샘플을 대상으로 초기 품질 테스트를 수행 | K29: 상용 솔루션이나 오픈소스가 아닌 제논 자사 파서 솔루션으로 이해됨. HWP 파싱 품질이 본 사업에 대단히 큰 비중을 차지하므로, 이 부분에 대한 초기 품질 테스트가 선행되어야 할 것으로 판단됨. | Q29: 완료 | R29: 수용 | S29: 수용 | T29: 46255
E30: SFR-002-02-02 | G30: (품질 검증) 변환 과정의 레이아웃 손실, 표 깨짐, 특수문자 누락 등 자동 검출 기능 | H30: RFP | I30: 제논 | J30: 변환 과정의 레이아웃 손실, 표 깨짐, 특수문자 누락 등 자동 검출 기능 제공, 플랫폼의 Admin 화면에서 확인 가능 | Q30: 완료 | R30: 수용 | S30: 수용 | T30: 46232
E31: SFR-002-02-03 | G31: 시스템은 (원본 대조) 변환 결과물에 대한 원본 대조 미리보기 기능 제공하여야 한다. | H31: RFP | I31: 제논 | J31: 플랫폼을 통해 변환 결과물에 대한 원본 대조 미리보기 기능 제공 | Q31: 완료 | R31: 수용 | S31: 수용 | T31: 46232
E32: SFR-002-03-01 | F32: 청킹(Chunking) 전략 설정 및 적용 ※ 기본 청킹 전략 및 청크 크기 권장 범위는 구축 시 위원회와 협의하여 확정 | G32: 시스템은 문서 유형 및 구조에 따라 최적화된 청킹 전략을 적용하고 관리자가 파라미터를 조정할 수 있는 기능 제공하여야 한다. | H32: RFP | I32: 제논 | J32: [Before] 플랫폼에서 벡터 DB 적재 시 chunk_size 등 청킹 파라미터 지정 기능 제공 (기본 청킹 전략 및 청크 크기 권장 범위는 구축 시 위원회와 협의하여 확정) [After] 플랫폼에서 벡터 DB 적재 시 문서 유형별 청킹 전략(구조/의미 기반), chunk size, overlap 등 파라미터를 조회·수정할 수 있도록 Web UI 제공 (기본 청킹 전략 및 청크 크기 권장 범위는 구축 시 위원회와 협의하여 확정) | K32: '청크 크기' 등 파라미터 변수는 관리자가 Web UI 수정 기능 필요. 청킹 전략, 청크 크기 등은 실제 학습 문서를 처리하면서 최적의 값을 조정하는 방향으로 진행 요청 | Q32: 완료 | R32: 수용 | S32: 수용 | T32: 46255
E33: SFR-002-03-02 | G33: (구조 분석) 문서의 의미 및 구조(표, 단락, 조항 등)를 분석하여 맥락이 유지되도록 분할 | H33: RFP | I33: 제논 | J33: [Before] 플랫폼에서 Semantic Chunking 기능으로 제공 [After] 플랫폼에서 벡터 DB 적재 시 문서 유형별 청킹 전략(구조/의미 기반), chunk size, overlap 등 파라미터를 조회·수정할 수 있도록 Web UI 제공 | K33: 문서 유형별로 구조 기반 분할과 의미 기반 분할을 선택 적용 필요 | Q33: 완료 | R33: 수용 | S33: 수용 | T33: 46255
E34: SFR-002-03-03 | G34: 시스템은 (메타데이터) 청킹 단위별 원문 위치(페이지, 조항 번호 등) 및 문서 식별 정보를 메타데이터로 저장하여야 한다. | H34: RFP | I34: 제논 | J34: [Before] 플랫폼에서 메타데이터 저장방식 제공 [After] 플랫폼에서 메타데이터 저장방식 제공 위원회 제공 문서를 분석하여 문서 유형별 메타데이터 초안을 제시 청크에는 문서ID·파일명·페이지·장/절/조항·원문 위치·버전·시행일·출처 경로 등을 저장하고, 최종 항목과 필수 여부는 위원회와 협의하여 확정 | K34: 청크 단위로 저장되는 메타데이터 항목 목록에 구체적 협의 필요. 제공한 문서(규정, 방법서 매뉴얼 등)를 통해 어떤 메타 유형을 추출할 수 있는지 초안을 제공 후 구체화하는 방식 희망 | Q34: 완료 | R34: 수용 | S34: 수용 | T34: 46255
E35: SFR-002-03-04 | G35: (이미지·도식 처리) 문서 내 이미지·도식은 관련 텍스트와 동일 청크에 포함하거나 별도 메타데이터로 연결하여, 검색 시 맥락 유지 | H35: RFP | I35: 제논 | J35: 플랫폼에서 문서 내 이미지·도식은 관련 텍스트와 동일 청크에 포함하거나 별도 메타데이터로 연결하는 기능 제공 | Q35: 완료 | R35: 수용 | S35: 수용 | T35: 46232
E36: SFR-002-03-05 | G36: (유형별 규칙) 문서 유형별(협약/세칙/방법서/매뉴얼/FAQ 등) 청킹 규칙 템플릿 기본 제공, 관리자가 웹 UI에서 설정·수정 가능 | H36: RFP | I36: 제논 | J36: 문서 유형별(협약/세칙/방법서/매뉴얼/FAQ 등) 청킹 규칙 템플릿 기본 제공, 관리자가 웹 UI에서 설정·수정 기능 제공 | Q36: 완료 | R36: 수용 | S36: 수용 | T36: 46232
E37: SFR-002-03-06 | G37: (파라미터 설정) 청크 크기, 오버랩 범위를 관리자 화면에서 조정 가능 | H37: RFP | I37: 제논 | J37: 플랫폼 관리자 화면에서 기능 제공 | Q37: 완료 | R37: 수용 | S37: 수용 | T37: 46232
E38: SFR-002-04-01 | F38: 청크 검수 및 교정 | G38: 시스템은 청크 데이터를 관리자가 검수할 수 있는 웹 기반 UI 제공하여야 한다. | H38: RFP | I38: 제논 | J38: [Before] 플랫폼에서, 문서 청크 단위 메타 수정 UI 및 문서 전체 단위 메타 수정 UI 제공 [After] 플랫폼에서, 문서 청크 단위 메타 수정 UI 및 문서 전체 단위 메타 수정 UI 제공 청크 검수 화면에서 메타데이터뿐 아니라 청크 본문 텍스트, 원문 위치 및 전후 문맥을 함께 조회·수정할 수 있도록 제공 | K38: J열은 메타데이터 수정 UI만 기재하고 있어 청크 본문(텍스트) 자체의 검수·수정 가능 여부가 불명확함. SFR-002-04-03(청크 단위 즉시 수정)과 함께 본문 교정 기능 제공 여부를 수행방안에 포함 요청 | Q38: 완료 | R38: 수용 | S38: 수용 | T38: 46255
E39: SFR-002-04-02 | G39: 시스템은 (자동 플래그) 파싱 오류를 자동 플래그하고 오류 유형별 필터링 기능 제공하여야 한다. | H39: RFP | I39: 제논 | J39: 적재 성공/실패·에러 로그는 플랫폼에서 제공하고, 파싱 오류 유형별 자동 플래그·필터링은 추가로 개발하여 제공 | Q39: 완료 | R39: 수용 | S39: 수용 | T39: 46232
E40: SFR-002-04-03 | G40: (교정 도구) 청크 단위 즉시 수정 기능 제공, 수정 사항은 벡터 DB에 동기화 | H40: RFP | I40: 제논 | J40: [Before] 플랫폼에서 기능 제공 [After](누락) 청크 수정 저장 시 해당 청크를 재임베딩하여 벡터 저장소에 갱신하고, 반영 상태를 '대기/처리/완료/실패'로 표시 즉시 반영 또는 작업 큐 방식은 처리량을 고려하여 설계 시 확정하며, 반영 시각과 오류·재처리 이력을 제공 특정 청크 단위 즉시 수정은 GUI로 가능. | K40: 수정 사항의 벡터 DB 동기화 방식(즉시 재임베딩 여부, 반영 시점)을 처리방안에 보완 [3차 검토의견, 260822~23 검토] '청크 단위 즉시 수정 기능' '수정 사항의 벡터 DB 동기화 방식'에 대해 단순 '플랫폼 기능 제공'보다, 구체적으로 어떻게 운영부서에서 동 기능을 사용할 수 있는 지 협의 필요(환경변수, 파라미터를 통한 수정의 경우 운영부서에서 지속가능한 관리가 어려움) | Q40: 완료 | R40: 수용 | S40: 수용 | T40: 46259
...

Sheet 성능
A1: 요구사항정의서-비기능
A2: 사업명 | D2: 신용회복위원회 통합 AI 플랫폼 구축 사업 | H2: 업무 구분 | K2: 성능 요구사항 | P2: 작성자 | S2: 김현근
A3: 단계 | D3: 요구분석, 설계, 구현, 테스트, 전개 | H3: 작성일자 | K3: 2026.08.24 | P3: 버전 | S3: v.0.999
A5: 요구사항 분류 | B5: 요구사항 고유번호 | C5: 요구사항 명 | D5: 정의 | E5: 상세요구사항ID | F5: 상세요구사항명 | G5: 상세요구사항 설명 | H5: 요구사항 출처 | I5: 담당 수행사 | J5: 제약사항 및 처리(수행)방안 | K5: 위원회 검토 의견(26.8.12.) | L5: 산출정보(RFP 기준) | M5: 산출물(방법론 테일러링 결과서) | N5: 요구사항 상태 | O5: 중요도 | P5: 담당자 | Q5: 완료여부 | R5: 수행사 수용 여부 | S5: 위원회 수용 여부 | T5: 비고(변경처리내역 등)
A6: 성능 요구사항 | B6: PER-001 | C6: 성능 목표 수립 및 검수 기준 마련 | D6: 성능 목표 수립, 테스트·모니터링 체계 및 기술협상 검수 기준 마련 | E6: PER-001-01-01 | F6: [성능 목표 수립] | G6: 세부 아키텍처별 (AI 추론, 문서 처리, 검색, 웹 서비스 등) 성능 목표를 수립하고 달성 전략을 제안서에 포함 | H6: RFP | I6: 제논 | J6: AI 추론·문서처리·검색·웹 구간별 목표치·측정식·달성전략 수립 | L6: · 성능시험 계획서 · 성능시험 결과서 · 성능지표 정의서 · 통합 성능 테스트 시나리오 | Q6: 완료 | R6: 수용 | S6: 수용 | T6: 46246
E7: PER-001-01-02 | G7: 시스템은 성능 테스트 방안(부하 테스트, 스트레스 테스트 포함)을 수립하여야 한다. | H7: RFP | I7: 제논 | J7: 부하·스트레스 테스트 시나리오와 측정환경·합격기준 정의 | Q7: 완료 | R7: 수용 | S7: 수용 | T7: 46246
E8: PER-001-01-03 | G8: 성능 모니터링 및 이상 징후 탐지 체계를 구축 | H8: RFP | I8: 제논 | J8: 응답시간·오류율·자원사용률 모니터링 및 임계치 알림 구성 | Q8: 완료 | R8: 수용 | S8: 수용 | T8: 46246
E9: PER-001-01-04 | G9: 성능 병목 발생 시 대응 절차를 마련 | H9: RFP | I9: 제논 | J9: 병목 구간 식별→원인분석→튜닝→재시험 절차 수립 | Q9: 완료 | R9: 수용 | S9: 수용 | T9: 46246
E10: PER-001-02-01 | F10: [PER 공통 기술협상 협의 사항] | G10: PER 항목의 정량적 수치는 위원회가 요구하는 '목표 최소 합격 기준'이며, 사업자는 제안서에 각 항목별 달성 목표를 동 기준 이상으로 명시하는 것을 원칙으로 한다. | H10: RFP | I10: 제논 | J10: RFP 정량값을 최소 합격선으로 적용하고 항목별 상향 목표 제시 | Q10: 완료 | R10: 수용 | S10: 수용 | T10: 46246
E11: PER-001-02-02 | G11: 단, 현재 AI 기술 및 구현 환경의 한계로 인하여 부득이하게 상기 목표 기준 달성이 어렵다고 판단되는 항목에 대해서는, 제안서에 그 명확한 기술적 사유와 함께 '현실적으로 달성 가능한 대안 목표값'을 명시하여 제안할 수 있다. | H11: RFP | I11: 제논 | J11: 달성 곤란 항목은 기술 근거와 현실적 대안 목표값을 제시해 위원회 협의 | Q11: 완료 | R11: 수용 | S11: 수용 | T11: 46246
E12: PER-001-02-03 | G12: 항목별 최종 검수 합격 기준(목표값)은 제안사가 제시한 기술적 근거를 바탕으로 기술협상 시 위원회와 상호 협의하여 최종 확정한다. | H12: RFP | I12: 제논 | J12: 제안 목표와 기술 근거를 기준으로 기술협상에서 최종 합격값 확정 | Q12: 완료 | R12: 수용 | S12: 수용 | T12: 46246
A13: 성능 요구사항 | B13: PER-002 | C13: 웹 페이지 응답·문서 변환·검색 응답 성능 | D13: 웹 페이지 응답, 문서 파싱·변환 처리, 벡터 검색 응답 등 정량 기준 | E13: PER-002-01-01 | F13: [웹 페이지 응답 시간] | G13: 웹 페이지(관리자 대시보드, Agent 대화 화면, 검수 UI 등)는 사용 자 요청 시점부터 화면 렌더링 완료까지 3초 이내 응답 | H13: RFP | I13: 제논 | J13: 관리자·Agent·검수 UI 화면 렌더링 3초 이내 기준으로 계측 | L13: · PER-001 산출물에 포함 | Q13: 완료 | R13: 수용 | S13: 수용 | T13: 46246
E14: PER-002-01-02 | G14: 다음의 경우 예외 적용 · AI 추론이 포함된 페이지 · 5,000건 이상의 대량 데이터를 조회하는 경우 · 500KB 이상의 이미지를 포함하는 페이지 · 시스템 부하율이 70%를 초과하는 경우 | H14: RFP | I14: 제논 | J14: AI 추론·대량조회·대용량 이미지·고부하 조건은 예외구간으로 분리 측정 | Q14: 완료 | R14: 수용 | S14: 수용 | T14: 46246
E15: PER-002-02-01 | F15: [대용량 처리 지연 안내] | G15: 처리 시간이 5초를 초과하는 요청은 사용자에게 진행 상태 메시지 또는 프로그레스 바를 표시하여야 한다. | H15: RFP | I15: 제논 | J15: 5초 초과 작업에 진행상태 메시지 또는 프로그레스 바 표시 | Q15: 완료 | R15: 수용 | S15: 수용 | T15: 46246
E16: PER-002-03-01 | F16: [문서 변환 성능] | G16: 다중 포맷 문서(PDF, HWP, DOCX 등)의 파싱 및 HWP→PDF 변환 처리 성능 목표 수립 및 측정 | H16: RFP | I16: 제논 | J16: [Before] PDF·HWP·DOCX 파싱 및 HWP→PDF 변환을 포맷·용량별로 성능 측정 [After] PDF·HWPX·DOCX·PPT/PPTX 파싱 및 HWPX→PDF 변환을 포맷·용량별로 성능 측정 PDF·HWPX·DOCX·PPT/PPTX 등 포맷과 문서 용량·페이지 구간별 처리시간 목표 초안을 제시 목표값과 측정환경·반복횟수·합격기준을 위원회와 합의한 후 성능시험을 수행하고 결과를 제출 | K16: 성능 목표 수립에 대한 내용 없이 '측정'만 수행방안으로 제시되어 있음. 목표 제시-발주사 협의-성능측정 방식으로 수행 필요 다중 포맷 문서 파싱 대상의 '등'에 근거하여 PPT(PPTX) 추가 요청 | Q16: 완료 | R16: 수용 | S16: 수용 | T16: 46255
E17: PER-002-04-01 | F17: [검색 응답 성능] | G17: 단일 질의 검색 응답: 1초 이내 | H17: RFP | I17: 제논 | J17: 단일 질의 검색 응답 1초 이내 부하시험 | Q17: 완료 | R17: 수용 | S17: 수용 | T17: 46246
E18: PER-002-04-02 | G18: 하이브리드 검색(키워드+벡터) 합산 응답: 3초 이내 | H18: RFP | I18: 제논 | J18: 키워드+벡터 하이브리드 검색 3초 이내 부하시험 | Q18: 완료 | R18: 수용 | S18: 수용 | T18: 46246
A19: 성능 요구사항 | B19: PER-003 | C19: AI 서비스 유형별 동시접속 및 응답 성능 | D19: 서비스 유형별 동시접속·응답시간 및 시스템 자원 사용률 기준 | E19: PER-003-01-01 | F19: [사용자 그룹 정의 및 접속 형태: 총 928명] ※ 상기 인원은 ‘28년 말 기준 인력현황을 가정 | G19: [그룹A] 콜센터 상담사: '콜센터 상담 어시스턴트' 전용. STT 분석은 기 구축된 자원을 활용하며, 본 접속 형태에서는 상담 중 사용자의 LLM 호출 액션을 트리거(통화당 3회 이내)로 하여 추천 상담 스크립트(3종 이내)를 제공하는 기능에 한정함. (※ 참고: 일평균 콜 약 22,000건) · 대상 인원: 228명 · 활성사용율: 90% (휴가 등) · 통화가동률: 70% (동시 통화 진행 인력) · 동시성계수: 20% (통화 중 호출 시점의 중첩 확률) · 최종 동시접속자: 30명 (228명 * 90% * 70% * 20%) | H19: RFP | I19: 위고 | J19: 콜센터 228명·동시 30명 기준, 통화당 3회 이내 추천 스크립트 호출 부하 검증 | L19: · PER-001 산출물에 포함 | Q19: 완료 | R19: 수용 | S19: 수용 | T19: 46246
E20: PER-003-01-02 | G20: [그룹B] 상담부서(지부): 'Agent 상담지식'을 주로 사용하며, 그 외 AI 서비스도 허용. (※ 참고: 일평균 상담건수 12건, 평균 상담시간 30분, 1인이 상담 1건 당 2회 사용 가정) · 대상 인원: 433명 · 활성사용율: 85% (휴가, 출장 등) · 동시성계수: 15% (챗봇 호출 시점의 중첩 확률) · 최종 동시접속자: 55명 (433명 * 85% * 15%) | H20: RFP | I20: 제논 | J20: 상담부서 433명·동시 55명 기준 Agent 상담지식 혼합 부하 검증 | Q20: 완료 | R20: 수용 | S20: 수용 | T20: 46246
E21: PER-003-01-03 | G21: [그룹C] 지원부서(본부): 그룹 A, B의 메인기능을 제외한 기능을 주로 사용함 · 대상 인원: 268명 · 활성사용율: 85% (휴가 등) · 동시성계수: 10% · 최종 동시접속자: 23명 (268명 * 85% * 10%) | H21: RFP | I21: 제논 | J21: 지원부서 268명·동시 23명 기준 기타 Agent 혼합 부하 검증 | Q21: 완료 | R21: 수용 | S21: 수용 | T21: 46246
E22: PER-003-02-01 | F22: 콜센터 상담 어시스턴트(SFR) 성능 | G22: 시스템은 상담사의 AI 호출 액션(추천 스크립트 요청) 시, 스트리밍 첫 토큰 응답 시간 5초 이내를 보장하여야 한다(동시 LLM 요청 약 30 건 기준). 측정 구간은 상담사가 AI 호출 버튼을 클릭한 시점부터 첫 토큰이 UI에 표시되는 시점까지로 하며, STT 수신 및 백그라운드 맥 락 분석 시간은 측정 구간에 포함하지 않는다. | H22: RFP | I22: 위고 | J22: 동시 LLM 30건에서 호출 클릭→첫 토큰 표시 5초 이내 검증(STT·백그라운드 분석 제외) | Q22: 완료 | R22: 수용 | S22: 수용 | T22: 46246
E23: PER-003-03-01 | F23: Agent 상담지식 성능 | G23: 시스템은 상담지식 Agent의 단일 질의에 대해, 의도 분류·라우팅·검 색·응답 생성을 포함한 end-to-end 스트리밍 첫 토큰 응답 시간 5초 이내를 보장하여야 한다(동시접속자 55명 기준). | H23: RFP | I23: 제논 | J23: 동시 55명에서 의도분류·라우팅·검색·생성 포함 첫 토큰 5초 이내 검증 | Q23: 완료 | R23: 수용 | S23: 수용 | T23: 46246
E24: PER-003-04-01 | F24: 그 외 Agent | G24: 시스템 그 외 Agent의 스트리밍 첫 토큰 응답 시간 10초 이내를 보 장하여야 한다(동시접속자 23명 기준).P | H24: RFP | I24: 제논 | J24: 동시 23명에서 기타 Agent 첫 토큰 10초 이내 검증 | Q24: 완료 | R24: 수용 | S24: 수용 | T24: 46246
E25: PER-003-04-02 | G25: 단, Agent 데이터 길잡이는 코드 생성·실행·결과 정리를 포함한 전체 응답 완료 시간은 20초 이내를 보장하여야 한다(동시접속자 23명 기준). | H25: RFP | I25: 제논 | J25: PER-003-04-02 에서 전체 응답 완료 시간 20초 이내를요구에 대해 다음의 2가지 케이스로 분리하여 1번 항목에서만 20초 이내 답변. 1) 데이터에 따라 파라미터만 바뀌는 수준의 코드 생성 2) 자유 분석 및 고급 통계 분석, 대용량 데이터 입력 [26.07.30 Agent 개발 요구사항 논의] | Q25: 완료 | R25: 수용 | S25: 수용 | T25: 46259
E26: PER-003-05-01 | F26: [시스템 자원 사용률 기준] | G26: 시스템은 PER에서 정의한 동시접속 환경(108명)에서 다음 자원 사용률 기준을 충족하여야 한다. | H26: RFP | I26: 제논 | J26: 동시접속 108명 부하에서 CPU·메모리·GPU 사용률 기준 검증 | Q26: 완료 | R26: 수용 | S26: 수용 | T26: 46246
E27: PER-003-05-02 | G27: CPU 평균 사용률: 서비스 가용시간(09:00~18:00) 동안 70% 이하 | H27: RFP | I27: 제논 | J27: 업무시간 CPU 평균 사용률 70% 이하 모니터링 | Q27: 완료 | R27: 수용 | S27: 수용 | T27: 46246
E28: PER-003-05-03 | G28: 메모리 평균 사용률: 서비스 가용시간 동안 80% 이하 | H28: RFP | I28: 제논 | J28: 업무시간 메모리 평균 사용률 80% 이하 모니터링 | Q28: 완료 | R28: 수용 | S28: 수용 | T28: 46246
E29: PER-003-05-04 | G29: GPU 사용률: 피크 부하 시 GPU당 평균 사용률 85% 이하 (LLM 추론 특성상 순간 100% 도달은 허용하되, 5분 평균 기준 적용. 상시 95% 이상 지속 시 자원 증설 필요 판정) | H29: RFP | I29: 제논 | J29: 피크 부하 GPU 5분 평균 85% 이하, 상시 95% 초과 시 증설 판단 | Q29: 완료 | R29: 수용 | S29: 수용 | T29: 46246
E30: PER-003-05-05 | G30: 상기 기준은 정상 운영 상태에서 적용하며, 배치 파이프라인 실행(증 분 인덱싱, 재임베딩 등) 시간대는 위원회와 협의하여 측정 대상에서 제외할 수 있다. | H30: RFP | I30: 제논 | J30: 증분 인덱싱·재임베딩 배치시간은 위원회 협의 후 측정구간에서 분리 | Q30: 완료 | R30: 수용 | S30: 수용 | T30: 46246
A31: 성능 요구사항 | B31: PER-004 | C31: RAG 응답 정확도·환각률·문서 분류 | D31: RAG 정확도·환각률·출처 정밀도, 문서 분류·메타데이터·검색 품질 | E31: PER-004-01-01 | F31: [RAG 응답 정확도] | G31: 위원회 제공 테스트케이스(정답 문항 최소 50개 이상)에서 응답 정확도 측정 · 최소 합격 기준: 85% 이상 · 목표 정확도: 90% 이상 | H31: RFP | I31: 제논 | J31: 위원회 정답셋 50건 이상으로 응답 정확도 85% 합격·90% 목표 검증 | L31: · PER-001 산출물에 포함 · 조치결과보고서(성능 미달 시 보완•수정 결과) | Q31: 완료 | R31: 수용 | S31: 수용 | T31: 46246
E32: PER-004-02-01 | F32: [환각률(Hallucination Rate)] | G32: 테스트케이스 기준 10% 이하 | H32: RFP | I32: 제논 | J32: 위원회 테스트케이스 기준 환각률 10% 이하 검증 | Q32: 완료 | R32: 수용 | S32: 수용 | T32: 46246
E33: PER-004-03-01 | F33: [출처 인용 정밀도] | G33: 85% 이상 | H33: RFP | I33: 제논 | J33: 답변 근거의 출처 인용 정밀도 85% 이상 검증 | Q33: 완료 | R33: 수용 | S33: 수용 | T33: 46246
E34: PER-004-04-01 | F34: [문서 자동 분류 정확도] | G34: · 85% 이상 · 검수 방법: 위원회 제공 검증 데이터셋 기반 측정 | H34: RFP | I34: 제논 | J34: 위원회 검증셋으로 문서 자동분류 정확도 85% 이상 측정 | Q34: 완료 | R34: 수용 | S34: 수용 | T34: 46246
E35: PER-004-05-01 | F35: [메타데이터 자동 추출 정확도] | G35: 문서 내 핵심 메타데이터(시행일, 폐지일, 적용대상, 제도구분) 자동 추출 정확도. · 최소 합격 기준 85% (문서 단위 측정: 검증 데이터셋 내 문서 중 필수 메타데이터 전 항목이 정확히 추출된 문서의 비율로 산정) | H35: RFP | I35: 제논 | J35: 시행일·폐지일·적용대상·제도구분 전 항목 일치 문서 비율 85% 이상 검증 | Q35: 완료 | R35: 수용 | S35: 수용 | T35: 46246
E36: PER-004-06-01 | F36: [도메인 용어 검색 재현율] | G36: · 85% 이상 · 검수 방법: 위원회 제공 검증 데이터셋 기반 측정 | H36: RFP | I36: 제논 | J36: 위원회 용어 검증셋으로 검색 재현율 85% 이상 측정 | Q36: 완료 | R36: 수용 | S36: 수용 | T36: 46246
E37: PER-004-07-01 | F37: [검수 기준] | G37: 검수 샘플 규모·측정 방법은 기술협상 시 협의하여 확정한다. | H37: RFP | I37: 제논 | J37: 샘플 규모·산식·판정기준을 기술협상에서 협의·확정 | Q37: 완료 | R37: 수용 | S37: 수용 | T37: 46246
A38: 성능 요구사항 | B38: PER-005 | C38: RAG 이상 징후 탐지·벡터 DB 복구(RTO) | D38: RAG 품질 이상 징후 탐지·알림, 벡터 DB 장애 시 복구(RTO) | E38: PER-005-01-01 | F38: [이상 징후 탐지 기본 원칙] | G38: RAG 품질 모니터링 대시보드에서 다음 지표의 이상 징후 탐지 및 관리자 알림 제공 · 환각률 급증 · 응답 시간 지연 · 검색 실패율 급증 · 응답 정확도 하락 | H38: RFP | I38: 제논 | J38: 환각률·응답지연·검색실패율·정확도 저하를 대시보드에서 탐지·알림 | L38: · PER-001 산출물에 포함 | Q38: 완료 | R38: 수용 | S38: 수용 | T38: 46246
E39: PER-005-01-02 | G39: 각 지표의 임계값은 관리자가 웹 UI에서 직접 조정 가능하도록 구현 | H39: RFP | I39: 제논 | J39: 이상징후 임계값과 알림정책을 관리자 Web UI에서 조정 | Q39: 완료 | R39: 수용 | S39: 수용 | T39: 46246
E40: PER-005-02-01 | F40: [벡터 DB 복구 시간(RTO)] | G40: 벡터 DB 장애 발생 시 백업 데이터 활용 전체 복구 필요 | H40: RFP | I40: 제논 | J40: 벡터DB 장애 시 백업 기반 전체 복구 및 RTO 측정 | Q40: 완료 | R40: 수용 | S40: 수용 | T40: 46246
E41: PER-005-02-02 | G41: 운영 중 데이터 규모 증가에 따른 RTO 재산정은 운영 단계에서 별도 협의 | H41: RFP | I41: 제논 | J41: 데이터 증가량을 반영해 운영 단계 RTO 재산정 | Q41: 완료 | R41: 수용 | S41: 수용 | T41: 46246
...

Sheet 시스템장비
A1: 요구사항정의서-비기능
A2: 사업명 | D2: 신용회복위원회 통합 AI 플랫폼 구축 사업 | H2: 업무 구분 | K2: 시스템장비 요구사항 | P2: 작성자 | S2: 김현근
A3: 단계 | D3: 요구분석, 설계, 구현, 테스트, 전개 | H3: 작성일자 | K3: 2026.08.24 | P3: 버전 | S3: v.0.999
A5: 요구사항 분류 | B5: 요구사항 고유번호 | C5: 요구사항 명 | D5: 정의 | E5: 상세요구사항ID | F5: 상세요구사항명 | G5: 상세요구사항 설명 | H5: 요구사항 출처 | I5: 담당 수행사 | J5: 제약사항 및 처리(수행)방안 | K5: 위원회 검토 의견(26.8.12.) | L5: 산출정보(RFP 기준) | M5: 산출물(방법론 테일러링 결과서) | N5: 요구사항 상태 | O5: 중요도 | P5: 담당자 | Q5: 완료여부 | R5: 수행사 수용 여부 | S5: 위원회 수용 여부 | T5: 비고(변경처리내역 등)
A6: 시스템 장비 요구사항 | B6: ECR-001 | C6: 시스템 납품 및 계약 조건 | D6: 시스템 납품 및 계약 기준 정의 | E6: ECR-001-01-01 | F6: [시스템 납품 및 계약 조건] | G6: 제안요청서 사양은 최소 기준이며, 사업자는 성능·확장성을 고려한 최적 구성을 제안하여야 한다. | H6: RFP | I6: 제논 | J6: RFP 최소사양 기준 성능·확장성 검토 및 최적 구성안 제시 | L6: · 요구사항 충족 매핑표 · 납품확인서 · 정품 확인서(제품보증서) · 라이선스 증서 (상용 SW•구독형 포함) · 제조사 기술지원확약서 (HW•SW) · 제조사 물품공급확약서 | Q6: 완료 | R6: 수용 | S6: 수용 | T6: 46246
E7: ECR-001-01-02 | G7: HW/SW/NW 구성은 상호연동성, 운영편의성, 비용효율성을 고려하여 설계하여야 한다. | H7: RFP | I7: 제논 | J7: H/W·S/W·N/W 상호연동성·운영편의성·비용효율성 기반 구성 설계 | Q7: 완료 | R7: 수용 | S7: 수용 | T7: 46246
E8: ECR-001-01-03 | G8: 제안 구성에 대한 요구사항 충족 여부 매핑표를 제출하여야 한다. | H8: RFP | I8: 제논 | J8: 도입 구성별 요구사항 충족 매핑표 작성·제출 | Q8: 완료 | R8: 수용 | S8: 수용 | T8: 46246
E9: ECR-001-01-04 | G9: 모든 도입 제품은 정품 및 최신 안정화 버전으로 구성하되 제조사/커뮤니티의LTS 또는 프로덕션 권장 버전을 우선 적용 하여야 한다. | H9: RFP | I9: 제논 | J9: 정품·최신 안정화/LTS 버전 적용 및 제조사 기술지원 체계 확보 | Q9: 완료 | R9: 수용 | S9: 수용 | T9: 46246
E10: ECR-001-01-05 | G10: 납품되는 서버는 직접 제조사의 정품이어야 하며, 기존 운영 인프라(Dell, HP 계열)와의 관리 일관성 확보를 위해 동일 벤더 또는 동등 수준의 통합 관리 솔루션 지원 방안을 제안서에 명시하여야 한다.대해서는 제조사 기술지원 체계를 명시한다. | H10: RFP | I10: 제논 | J10: 제조사 정품 서버 적용, 기존 Dell·HP 인프라와 동등한 통합관리 및 5년 기술지원 체계 명시 | Q10: 완료 | R10: 수용 | S10: 수용 | T10: 46246
E11: ECR-001-01-06 | G11: 라이선스는 설치형 우선으로 하며, 구독형은 최소 1년 이상 포함하여야 한다. | H11: RFP | I11: 제논 | J11: 설치형 라이선스 우선 적용, 구독형은 최소 1년 이상 확보 | Q11: 완료 | R11: 수용 | S11: 수용 | T11: 46246
E12: ECR-001-01-07 | G12: 납품 장비는 최소 5년 이상 Warranty 및 기술지원이 가능하여야 한다. | H12: RFP | I12: 제논 | J12: 납품 장비는 최소 5년 이상 Warranty 및 기술지원이 가능 | Q12: 완료 | R12: 수용 | S12: 수용 | T12: 46246
E13: ECR-001-01-08 | G13: 설치, 커스터마이징, 테스트, 전환 작업은 사업자가 수행한다. | H13: RFP | I13: 제논 | J13: 설치, 커스터마이징, 테스트, 전환 작업은 사업자가 수행 | Q13: 완료 | R13: 수용 | S13: 수용 | T13: 46246
E14: ECR-001-01-09 | G14: 추가 HW/SW 필요 시 상호 협의하여 반영한다. | H14: RFP | I14: 제논 | J14: 추가 HW/SW 필요 시 협의하여 반영 다만, 과업범위를 초과(과업 예산범위를 초과)하는 경우 과업변경절차에 따라 위원회와 협의하여 상호 합의된 범위에서 반영함 | Q14: 완료 | R14: 수용 | S14: 수용 | T14: 46246
E15: ECR-001-01-10 | G15: 동급 이상의 대체 아키텍처 및 기술 적용을 허용한다. | H15: RFP | I15: 제논 | J15: 동급 이상의 대체 아키텍처 및 기술 적용을 허용 다만, 대체 아키텍처 및 기술적용 필요 시 허용 적용 범위는 위원회와 협의하여 상호 합의된 범위에서 적용함 | Q15: 완료 | R15: 수용 | S15: 수용 | T15: 46246
A16: 시스템 장비 요구사항 | B16: ECR-002 | C16: 논리 아키텍처 및 서비스 구성 | D16: AI 서비스 중심 시스템 구조 정의 | E16: ECR-002-01-01 | F16: [논리 아키텍처 및 서비스 구성] | G16: AI 플랫폼, RAG 기반 검색, 상담 어시스턴트 기능을 포함한 구조를 구성하여야 한다. | H16: RFP | I16: 제논 | J16: AI 플랫폼, RAG 기반 검색, 상담 어시스턴트 기능을 포함한 구조를 구성 | L16: · 시스템 아키텍처 설계서 · 네트워크 구성도 | Q16: 완료 | R16: 수용 | S16: 수용 | T16: 46246
E17: ECR-002-01-02 | G17: 각 구성요소는 모듈화되어 독립적 확장 및 변경이 가능하여야 한다. | H17: RFP | I17: 제논 | J17: 각 구성요소는 모듈화되어 독립적 확장 및 변경이 가능 | Q17: 완료 | R17: 수용 | S17: 수용 | T17: 46246
E18: ECR-002-01-03 | G18: 데이터 처리 구조(데이터 플랫폼, 파이프라인 등)는 선택적으로 제안할 수 있다. | H18: RFP | I18: 제논 | J18: 데이터 처리 구조(데이터 플랫폼, 파이프라인 등)는 수행사 도입 플랫폼을 기본적으로 사용하는 것을 원칙으로하며, 처리구조에 대한 위원회 별도 의견이 있는 경우, 위원회와 협의하여 적용함 | Q18: 완료 | R18: 수용 | S18: 수용 | T18: 46246
E19: ECR-002-01-04 | G19: 기존 계정계, KMS, 그룹웨어 등 내부 시스템과 연계 가능한 구조를 제공하되 구현 범위 및 허용에 대한 부분은 협의 후 진행한다. | H19: RFP | I19: 제논 | J19: 계정계·KMS·그룹웨어 연계 구조 적용, 구현범위는 위원회 협의·확정 | Q19: 완료 | R19: 수용 | S19: 수용 | T19: 46246
E20: ECR-002-01-05 | G20: 표준 API 기반 연계를 지원해야 하며 시스템 간 결합도를 최소화하여야 한다. | H20: RFP | I20: 제논 | J20: 표준 API 기반 연계를 지원하고 시스템 간 결합도를 최소화 | Q20: 완료 | R20: 수용 | S20: 수용 | T20: 46246
E21: ECR-002-01-06 | G21: 특정 제품, 특정 아키텍처(Kubernetes, 특정 DB 등)에 종속되지 않아야 한다. | H21: RFP | I21: 제논 | J21: 특정 제품, 특정 아키텍처(Kubernetes, 특정 DB 등)에 종속되지 않도록 시스템 구조를 설계 및 적용 | Q21: 완료 | R21: 수용 | S21: 수용 | T21: 46246
A22: 시스템 장비 요구사항 | B22: ECR-003 | C22: 인프라 및 HW 구성 | D22: 시스템 인프라 및 장비 구성 기준 정의 | E22: ECR-003-01-01 | F22: [인프라 및 HW 구성] | G22: 성능 및 용량 요구사항 · 동시 사용자 및 업무 처리량을 고려한 인프라를 구성하여야 한다. · AI 추론 처리 시 응답속도 및 처리량 기준을 충족하여야 한다. · 데이터 저장 및 검색 성능을 보장하여야 한다. | H22: RFP | I22: 제논 | J22: · 동시 사용자 및 업무 처리량을 고려한 인프라를 구성 · AI 추론 처리 시 응답속도 및 처리량 기준을 충족하는 인프라를 구성 · 데이터 저장 및 검색 성능을 보장하는 인프라를 구성 | L22: · 인프라 설계서 (물리•논리 구성) · H/W 구성도 및 시스템 구성도 · 네트워크 구성도 · 규격 확인서 (CPU•GPU•Memory 등 세부 사양 대조) · 장비설치 계획서 · 설치확인서(설치결과서) | Q22: 완료 | R22: 수용 | S22: 수용 | T22: 46246
E23: ECR-003-01-02 | G23: 확장성 및 가용성 · Compute, Storage, Network 자원은 수평 확장이 가능하여야 한다. · 장애 발생 시 서비스 지속이 가능한 고가용성(HA) 구조를 제공하여야 한다. 단, 학습 노드 및 모델 서빙용 스토리지(All-Flash NAS)는 단일 장비 구성을 허용하며, 장애 발생 시 이미 기동된 추론 서비스는 유지되나 신규 기동 및 모델 교체가 제한될 수 있음을 인지한다. NAS 장애에 대한 백업·복구SLA(RTO/RPO)는 별도 정의한다. · 시스템 증설 시 서비스 중단 없이 확장 가능하여야 한다. | H23: RFP | I23: 제논 | J23: · Compute, Storage, Network 자원은 수평 확장이 가능하도록 인프라 구성 · 장애 발생 시 서비스 지속이 가능한 고가용성(HA) 구조를 제공. 단, 학습 노드 및 모델 서빙용 스토리지(All-Flash NAS)는 단일 장비로 구성, 장애 발생 시 이미 기동된 추론 서비스는 유지되나 신규 기동 및 모델 교체가 제한될 수 있음. NAS 장애에 대한 백업·복구SLA(RTO/RPO)는 별도 정의 · 시스템 증설 시 서비스 중단 없이 확장 가능하도록 인프라 구성 | Q23: 완료 | R23: 수용 | S23: 수용 | T23: 46246
E24: ECR-003-01-03 | G24: HW 구성 요구사항 (구색) · GPU 기반 AI 연산 처리가 가능한 인프라를 구성하여야 한다. · 고성능 스토리지(NAS/SAN/분산스토리지 등)를 구성하여야 한다. · 고속 네트워크(10GbE 이상)를 지원하여야 한다. · 서버, 스토리지, 네트워크 장비는 이중화 구성을 고려하여야 한다. | H24: RFP | I24: 제논 | J24: · GPU 기반 AI 연산 처리가 가능한 인프라를 구성 · 고성능 스토리지(NAS/SAN/분산스토리지 등)를 구성 · 고속 네트워크(10GbE 이상)를 지원하는 인프라 구성 · 서버, 스토리지, 네트워크 장비는 이중화 구성 | Q24: 완료 | R24: 수용 | S24: 수용 | T24: 46246
E25: ECR-003-01-04 | G25: 참조 구성(최종 목표 형상) · GPU: NVIDIA H200 141GB × 8장(LLM 학습·대규모 추론) · GPU: NVIDIA L40S 48GB × 2장(서비스 추론·개발·검증·콜센터) · 컨테이너 오케스트레이션: Kubernetes 기반 고가용성 클러스터 · 원문·메타·청크·업무 데이터: RDB 정본, 벡터 인덱스: 재생성 가능한 파생 구조 · 고성능 스토리지와 25/100GbE 고속 네트워크 ※ 상세 노드 배치·이중화·전력·냉각·BOM은 최종 설계 및 위원회 승인으로 확정한다. | H25: RFP | I25: 제논 | J25: · GPU: NVIDIA H200 141GB × 8장(LLM 학습·대규모 추론)으로 도입 및 구성 · GPU: NVIDIA L40S 48GB × 2장(서비스 추론·개발·검증·콜센터) 도입 및 구성 · 컨테이너 오케스트레이션: Kubernetes 기반 고가용성 클러스터로 구성 · 원문·메타·청크·업무 데이터: RDB 정본, 벡터 인덱스: 재생성 가능한 파생 구조로 구성 · 고성능 스토리지와 25/100GbE 고속 네트워크으로 구성 ※ 상세 노드 배치·이중화·전력·냉각·BOM은 최종 설계 및 위원회 승인으로 확정 | Q25: 완료 | R25: 수용 | S25: 수용 | T25: 46246
E26: ECR-003-01-05 | G26: 동등성 및 유연성 · 명시된 구성과 동등 이상의 성능을 제공하는 대체 아키텍처를 허용한다. · 특정 HW/SW 제품 및 벤더에 종속되지 않는 구성을 요구한다. | H26: RFP | I26: 제논 | J26: · 명시된 구성과 동등 이상의 성능을 제공하는 대체 아키텍처로 구성 · 특정 HW/SW 제품 및 벤더에 종속되지 않는 아키텍처로 구성 | Q26: 완료 | R26: 수용 | S26: 수용 | T26: 46246
E27: ECR-003-02-01 | F27: [ML 예측 모델 연산 자원 운영 방침] | G27: ML 예측 모델(차기 변제금 납입 가능성 예측)의 학습 및 배치 추론은 AI 플랫폼 구축을 위해 도입되는 GPU 서버 자원을 공유하여 운영한다. | H27: RFP | I27: 제논 | J27: 차기 변제금 예측모델 학습·배치추론에 도입 GPU 자원 공유·할당 | Q27: 완료 | R27: 수용 | S27: 수용 | T27: 46246
E28: ECR-003-03-01 | F28: [예측 모델용 데이터 저장소] | G28: 본 사업에서 개발하는 예측 모델의 학습, 배치 예측, 결과 적재 및 운영에 필요한 범위의 데이터 저장 구조와 처리 기능은 포함된다. | H28: RFP | I28: 제논 | J28: 예측모델 학습·배치예측·결과적재·운영에 필요한 데이터 저장·처리 구조 포함 | Q28: 완료 | R28: 수용 | S28: 수용 | T28: 46246
E29: ECR-003-03-02 | G29: AI 플랫폼 인프라는 향후 타 플랫폼과의 연계를 고려한 확장 가능한 구조로 설계하여야 한다. | H29: RFP | I29: 제논 | J29: AI 플랫폼 인프라는 향후 타 플랫폼과의 연계를 고려한 확장 가능한 구조로 설계 | Q29: 완료 | R29: 수용 | S29: 수용 | T29: 46246
A30: 시스템 장비 요구사항 | B30: ECR-004 | C30: 운영 및 관리 체계 | D30: 시스템 운영 및 관리 기준 정의 | E30: ECR-004-01-01 | F30: [운영 및 관리 체계] | G30: 운영 편의성 · 일상적인 운영 작업(모니터링 확인, 서비스 재시작, 사용량 조회 등)은 웹 UI으로 비전문 인력도 수행 가능하여야 한다. 단, K8s 클러스터 관리, 모델 배포, 장애 복구 등 고급 운영 작업은 수행사가 제공하는 운영 매뉴얼을 기반으로 숙련된 엔지니어가 필요한 수준임을 명시한다. · 모니터링, 알람 확인, 서비스 상태 조회, 단순 재시작 등 일상 운영은 웹 UI로 제공하여야 한다. 모델 배포, 클러스터 확장 등 고급 작업은 CLI 또는 자동화 스크립트 기반으로 제공하되 상세 운영 절차서를 함께 납품하여야 한다. · 시스템 상태 및 자원 사용량을 통합 모니터링 할 수 있어야 하며, 상세 GPU 모니터링 방안은 별도 제시 필요하다. | H30: RFP | I30: 제논 | J30: [Before] 일상 운영은 Web UI, 고급 작업은 CLI·자동화 스크립트로 제공하고 GPU 포함 통합 모니터링 구성 [After] 일상 운영은 Web UI, 고급 작업은 CLI·자동화 스크립트로 제공하고 GPU 포함 통합 모니터링 구성 모니터링·알람·상태조회·재시작·사용량 조회 등 일상 작업은 비전문 운영자가 수행 가능한 UI로 구성 | K30: 일상적인 운영 작업'에 대한 Web UI 관련하여 개별 기능에 대한 관리 UI를 발주사와 공유하고 협의 후 개발 및 커스텀 진행 요청(GenOS 기능 대부분이 게시판 형태의 UI를 대부분의 기능 제어에 공용으로 사용하고 있는 것으로 추측되며, 운영부서 조작 편의성을 위해 기존 GenOS 기능에 대한 별도 커스텀이 필요한 부분에 대해 반드시 사전 협의 필요) | L30: · 운영 매뉴얼 (GPU•플랫폼•AI 모델 운영) · 장애 대응 및 성능 튜닝 가이드 · 백업•복구 절차서 · 기술 이전 계획서 | Q30: 완료 | R30: 수용 | S30: 수용 | T30: 46255
E31: ECR-004-01-02 | G31: 자동화 및 안정성 · 장애 감지 및 자동 복구(Self-healing) 기능을 제공하여야 한다. · 로그, 이벤트, 작업 이력을 관리할 수 있어야 한다. · 백업 및 복구 기능을 제공하여야 한다. | H31: RFP | I31: 제논 | J31: Self-healing·로그/이벤트/작업이력·백업/복구 자동화 적용 | Q31: 완료 | R31: 수용 | S31: 수용 | T31: 46246
E32: ECR-004-01-03 | G32: 운영 지원 · 구축 완료 후 최소 1년간 기술지원 및 운영지원을 제공하여야 한다. · GPU, 플랫폼, AI 모델 운영 관련 매뉴얼을 제공하여야 한다. · 장애 대응, 성능 튜닝, 운영 가이드를 포함하여야 한다. | H32: RFP | I32: 제논 | J32: 구축 후 1년 이상 기술지원, GPU·플랫폼·모델 운영 매뉴얼과 장애·튜닝 가이드 제공 | Q32: 완료 | R32: 수용 | S32: 수용 | T32: 46246
E33: ECR-004-01-04 | G33: 교육 및 기술 이전 · 운영 권한 및 지식의 단계적 이관 계획을 제출하여야 한다. | H33: RFP | I33: 제논 | J33: 교육 및 기술 이전·운영 권한 및 지식의 단계적 이관 계획을 제출 | Q33: 완료 | R33: 수용 | S33: 수용 | T33: 46246
A34: 시스템 장비 요구사항 | B34: ECR-005 | C34: 보안 및 성능 품질 | D34: 보안 및 시스템 품질 기준 정의 | E34: ECR-005-01-01 | F34: [보안 및 성능 품질] | G34: 보안 요구사항 · 기존 보안 솔루션(V3 등)은 베어메탈 서버(DB 서버· NAS 등)에 적용하고, K8s 컨테이너 환경은 K8s 기본RBAC, NetworkPolicy, Audit Log, 이미지 취약점 스캔으로 동등 수준의 보안을 확보한다. 컨테이너 환경에서의 기존 보안 솔루션 적용 가능 여부는 기술협 상 시 벤더와 협의하여 확정한다. · 사용자 인증 및 권한관리 기능을 제공하여야 한다. · 개인정보 보호 기능(마스킹 및 암호화)을 적용하여야 한다. · 모든 접근 및 처리에 대한 로그를 기록하여야 한다. | H34: RFP | I34: 제논 | J34: 베어메탈 보안제품과 K8s RBAC·NetworkPolicy·Audit·이미지 스캔을 병행하고 인증·마스킹·암호화·로그 적용 | L34: · 보안 점검 결과서 · 성능 테스트 결과서 | Q34: 완료 | R34: 수용 | S34: 수용 | T34: 46246
E35: ECR-005-01-02 | G35: 시스템 연계 및 안정성 · 기존 시스템과의 연계 시 운영 영향 최소화하여야 한다. · 데이터 정합성을 유지하여야 한다. · 시스템 간 인터페이스 안정성을 확보하여야 한다. | H35: RFP | I35: 제논 | J35: 기존 시스템 연계 영향 최소화, 데이터 정합성·인터페이스 안정성 확보 | Q35: 완료 | R35: 수용 | S35: 수용 | T35: 46246
E36: ECR-005-01-03 | G36: 성능 및 품질 보장 · 응답속도·처리량·동시접속 등 승인된 성능 기준을 충족하여야 한다. · 운영환경 구축 전에는 최종 GPU 형상(H200 8장·L40S 2장) 중 L40S 1장을 개발·검증용으로 배정하고, 기 구축 상담화면 테스트 환경과 연계하여야 한다. · 운영 전환 전에는 운영과 동등한 스테이징에서 STT 연동, 추천 스크립트, 개인정보 마스킹, 장애·성능·TA 이중화 시나리오를 검증하여야 한다. · 테스트 완료 후 개발·검증 자원은 승인된 운영 배치계획에 따라 전환하여야 한다. · 성능 저하 또는 장애 발생 시 개선 방안과 재검증 결과를 제출하여야 한다. | H36: RFP | I36: 제논 | J36: 운영동등 스테이징에서 STT·추천·마스킹·장애·성능·TA 이중화를 검증하고 승인된 운영 배치로 전환 | Q36: 완료 | R36: 수용 | S36: 수용 | T36: 46246
A37: 시스템 장비 요구사항 | B37: ECR-006 | C37: AI 플랫폼 장비 도입 | D37: AI 플랫폼 운영을 위한 서버·스토리지·네트워크 장비 도입 규격 정의 | E37: ECR-006-01-01 | F37: 공통 요구사항 (전체 서버, 장비 공통) | G37: 제시된 사양 이상이어야 하며, 동급 또는 상위 제안 허용 | H37: RFP | I37: 제논 | J37: 제시 사양 이상·동급/상위 장비로 납품 | L37: · 규격 확인서 (CPU•GPU•Memory•Storage 등 세부 사양 대조) · 장비설치 계획서 · 설치확인서(설치결과서) · 정품 확인서(제품보증서) · 라이선스 증서 (OS•관리도구 등) · 오픈소스 라이선스 검증 결과서 · 제조사 기술지원확약서 · 제조사 물품공급확약서 · 랙 전력•냉각•케이블링 설치 도면 | Q37: 완료 | R37: 수용 | S37: 수용 | T37: 46246
E38: ECR-006-01-02 | G38: OS는 LTS 버전(Rocky Linux 9.x / RHEL / AlmaLinux / Ubuntu LTS 등) 적용하여 최신 보안 패치 상태로 납품 상세 | H38: RFP | I38: 제논 | J38: Rocky Linux/RHEL/AlmaLinux/Ubuntu LTS 등 장기지원 OS와 최신 보안패치 적용 | Q38: 완료 | R38: 수용 | S38: 수용 | T38: 46246
E39: ECR-006-01-03 | G39: 시스템은 전원 공급장치(PSU), 팬(FAN)은 모두 이중화 Hot-Swap 지원하여야 한다. | H39: RFP | I39: 제논 | J39: 전원 공급장치(PSU), 팬(FAN)은 모두 이중화 Hot-Swap 지원 | Q39: 완료 | R39: 수용 | S39: 수용 | T39: 46246
E40: ECR-006-01-04 | G40: 시스템은 네트워크 인터페이스는 기존 스위치와 호환되는 SFP+/SFP28/100GbE 포트 제공하여야 한다. | H40: RFP | I40: 제논 | J40: 네트워크 인터페이스는 기존 스위치와 호환되는 SFP+/SFP28/100GbE 포트 제공 | Q40: 완료 | R40: 수용 | S40: 수용 | T40: 46246
E41: ECR-006-01-05 | G41: 모든 서버는 전용 관리포트(BMC) 포함 | H41: RFP | I41: 제논 | J41: 모든 서버는 전용 관리포트(BMC) 포함 | Q41: 완료 | R41: 수용 | S41: 수용 | T41: 46246
...

Sheet 인터페이스
A1: 요구사항정의서-비기능
A2: 사업명 | D2: 신용회복위원회 통합 AI 플랫폼 구축 사업 | H2: 업무 구분 | K2: 인터페이스 요구사항 | P2: 작성자 | S2: 김현근
A3: 단계 | D3: 요구분석, 설계, 구현, 테스트, 전개 | H3: 작성일자 | K3: 2026.08.24 | P3: 버전 | S3: v.0.999
A5: 요구사항 분류 | B5: 요구사항 고유번호 | C5: 요구사항 명 | D5: 정의 | E5: 상세요구사항ID | F5: 상세요구사항명 | G5: 상세요구사항 설명 | H5: 요구사항 출처 | I5: 담당 수행사 | J5: 제약사항 및 처리(수행)방안 | K5: 위원회 검토 의견(26.8.12.) | L5: 산출정보(RFP 기준) | M5: 산출물(방법론 테일러링 결과서) | N5: 요구사항 상태 | O5: 중요도 | P5: 담당자 | Q5: 완료여부 | R5: 수행사 수용 여부 | S5: 위원회 수용 여부 | T5: 비고(변경처리내역 등)
A6: 인터페이스 요구사항 | B6: INR-001 | C6: SSO 통합 인증·인사정보 연동 인터페이스 | D6: 한 번의 로그인으로 전체 시스템에 접근하는 통합 인증 환경 및 업무담당자 검색을 위한 인사정보시스템 연동 규격 정의 | E6: INR-001-01-01 | F6: [기존 SSO 체계 연동] | G6: - 시스템은 기존 위원회 SSO 체계와 연계하여 통합 로그인 기능을 제공하여야 한다. 단 한 번의 로그인으로 연결된 모든 대상 업무시스템으로 이동이 가능한 통합 인증 환경을 구축하여야 한다. 연동 대상 시스템 목록 및 연동 방식은 다음과 같다. · 기간계 시스템: 기존 SSO Agent 연동 · 신규 AI 플랫폼: 표준 프로토콜 기반 연동 | H6: RFP | J6: 위원회 SSO와 통합 로그인·단일 세션을 연동하고 대상 시스템·인증방식 협의·확정 | L6: · 인터페이스 설계서 · API 적용 가이드 | Q6: 완료 | R6: 수용 | S6: 수용 | T6: 46246
E7: INR-001-02-01 | F7: [플랫폼 호환성] | G7: - 시스템은 다음 운영 환경과의 호환성을 보장하여야 한다 · OS: UNIX, Linux (RHEL, CentOS, Ubuntu), Windows Server · WAS: WebLogic, JEUS, Tomcat, WildFly · 브라우저: Chrome, Edge (최신 버전 기준) | H7: RFP | J7: UNIX/Linux/Windows·WebLogic/JEUS/Tomcat/WildFly·Chrome/Edge 호환성 검증 | Q7: 완료 | R7: 수용 | S7: 수용 | T7: 46246
E8: INR-001-03-01 | F8: [연동 인터페이스 제공] | G8: - 시스템은 다양한 운영 환경을 고려한 전용 API와 Filter를 제공하여 기존 시스템 소스 수정을 최소화하여야 한다. 다음 연동 방식을 지원하여야 한다 · REST API 기반 인증 토큰 발급/검증 · Servlet Filter 기반 세션 연동 · SAML/OAuth 표준 프로토콜 지원 | H8: RFP | J8: [Before] 전용 API·Filter 제공으로 기존 시스템 소스 변경 최소화 [After] 전용 API·Filter 제공으로 기존 시스템 소스 변경 최소화 하기 연동 방식 중 시스템 적합성을 검토하여 우선순위를 부여하여 연동 방식 선정 · REST API 기반 인증 토큰 발급/검증 · Servlet Filter 기반 세션 연동 · SAML/OAuth 표준 프로토콜 지원 | K8: 별도 기재한 '연동방식'을 수행방안에서 제외한 부분에 대한 문의(G열에 나열한 연동방식을 모두 수용할 수 있는지 여부) | Q8: 완료 | R8: 수용 | S8: 수용 | T8: 46255
E9: INR-001-03-02 | G9: 연동 가이드 문서 및 샘플 코드를 제공하여야 한다. | H9: RFP | J9: 연동 가이드 문서 및 샘플 코드를 제공 | Q9: 완료 | R9: 수용 | S9: 수용 | T9: 46246
E10: INR-001-04-01 | F10: [인사정보시스템 또는 계정관리시스템(IM시스템) 연동 방식 및 프로토콜] | G10: - 인사정보시스템 또는 계정관리시스템(IM시스템) 과의 연동 방식을 정의하여야 한다. · API 연동: REST API (HTTPS), 실시간 조회 · 배치 연동: 파일 기반(CSV/XML) 또는 DB 직접 조회, 일 단위 동기화 | H10: RFP | J10: 인사·계정정보를 REST API 실시간 조회 또는 파일/DB 일배치 방식으로 연동 | Q10: 완료 | R10: 수용 | S10: 수용 | T10: 46246
E11: INR-001-04-02 | G11: 연동 방식의 최종 선정은 위원회와 협의하여 확정한다. | H11: RFP | J11: 인사·계정정보 연동 방식은 대상 시스템과 인터페이스 구조 검토 후 위원회 협의·확정 | Q11: 완료 | R11: 수용 | S11: 수용 | T11: 46246
E12: INR-001-05-01 | F12: [인사정보 연동 데이터 항목] | G12: - 수신 데이터 항목을 정의하여야 한다: · 필수: 사번, 성명, 부서명, 직급, 직책, 내선번호, 이메일 | H12: RFP | J12: 사번·성명·부서·직급·직책·내선·이메일을 인사정보 필수 연동항목으로 정의 | Q12: 완료 | R12: 수용 | S12: 수용 | T12: 46246
E13: INR-001-05-02 | G13: 데이터 형식(문자열/숫자), 최대 길이, 인코딩(UTF-8을 명시하여야 한다. | H13: RFP | J13: 연동 데이터 형식(문자열/숫자)·최대길이·UTF-8 인코딩 정의 | Q13: 완료 | R13: 수용 | S13: 수용 | T13: 46246
E14: INR-001-06-01 | F14: [인사정보 동기화 주기 및 정합성] | G14: 배치 동기화 주기(일 1회/주 1회)의 기본값 및 관리자 조정 범위를 정의하여야 한다. | H14: RFP | J14: 배치 동기화 주기(일 1회/주 1회)의 기본값 및 관리자 조정 범위를 정의 | Q14: 완료 | R14: 수용 | S14: 수용 | T14: 46246
E15: INR-001-06-02 | G15: 인사이동·퇴직 등 변경 발생 시 동기화 처리 방식(전체 교체/증분 반영)을 정의하여야 한다. | H15: RFP | J15: 인사이동·퇴직 등 변경 발생 시 동기화 처리 방식(전체 교체/증분 반영)을 정의 | Q15: 완료 | R15: 수용 | S15: 수용 | T15: 46246
A16: 인터페이스 요구사항 | B16: INR-002 | C16: 언어모델 표준 인터페이스 | D16: 언어모델 교체 시 상위 서비스 영향을 최소화하기 위한 표준 인터페이스 구조 정의 | E16: INR-002-01-01 | F16: [모델 추상화 레이어] | G16: 시스템은 상위 서비스(Agent, RAG 등)와 하위 언어모델 간 결합도 를 최소화하는 추상화 레이어를 제공하여야 한다. | H16: RFP | J16: 상위 서비스(Agent, RAG 등)와 하위 언어모델 간 결합도 를 최소화하는 추상화 레이어를 제공 | L16: · 인터페이스 설계서 · API 적용 가이드 | Q16: 완료 | R16: 수용 | S16: 수용 | T16: 46246
E17: INR-002-01-02 | G17: 모델 교체 또는 업그레이드 시 상위 서비스의 코드 수정 없이 설정 변경만으로 전환이 가능하여야 한다. | H17: RFP | J17: 모델 교체 또는 업그레이드 시 상위 서비스의 코드 수정 없이 설정 변경만으로 전환이 가능 | Q17: 완료 | R17: 수용 | S17: 수용 | T17: 46246
E18: INR-002-02-01 | F18: [표준 API 호환] | G18: 모델 연동 API는 OpenAI API 호환 형식을 지원하여야 한다. | H18: RFP | J18: 모델 연동 API는 OpenAI API 호환 형식을 지원 | Q18: 완료 | R18: 수용 | S18: 수용 | T18: 46246
E19: INR-002-02-02 | G19: 향후 정부 표준 모델 API 규격 제정 시 해당 규격으로 전환이 용이 한 구조여야 한다. | H19: RFP | J19: 향후 정부 표준 모델 API 규격으로 용이하게 전환 가능한 구조 적용 | Q19: 완료 | R19: 수용 | S19: 수용 | T19: 46246
E20: INR-002-02-03 | G20: API 버전 관리를 통해 하위 호환성을 보장하여야 한다. | H20: RFP | J20: API 버전 관리를 통해 하위 호환성을 보장 | Q20: 완료 | R20: 수용 | S20: 수용 | T20: 46246
E21: INR-002-03-01 | F21: [서비스-모델 매핑 구성] | G21: 각 AI 서비스 (Agent)는 독립된 언어모델 인스턴스에 연결되며, 서비스별 모델 할당은 설정을 통해 관리되어야 한다. | H21: RFP | J21: 각 AI 서비스 (Agent)는 독립된 언어모델 인스턴스에 연결되며, 서비스별 모델 할당은 설정을 통해 관리 | Q21: 완료 | R21: 수용 | S21: 수용 | T21: 46246
E22: INR-002-03-02 | G22: 서비스-모델 매핑 구성은 코드 변경 없이 설정 파일 또는 관리자 화면을 통해 변경 가능하여야 한다. | H22: RFP | J22: 서비스-모델 매핑 구성은 코드 변경 없이 설정 파일 또는 관리자 화면을 통해 변경 가능 | Q22: 완료 | R22: 수용 | S22: 수용 | T22: 46246
A23: 인터페이스 요구사항 | B23: INR-003 | C23: 내부 업무포털 지식 수집 인터페이스 | D23: 수집 인터페이스 제공 | E23: INR-003-01-01 | F23: 데이터 수집 파이프라인 인터페이스를 제공 | G23: 시스템은 내부 업무포털 중 위원회가 지정하는 게시판에 등록되는 게시글의 본문 및 첨부파일을 상담지식 Agent 지식베이스로 반자동 수집할 수 있는 데이터 수집 파이프라인 인터페이스를 제공하여야 한다. | H23: RFP | J23: 지정 게시판 본문·첨부파일을 상담지식 Agent 지식베이스로 반자동 수집 | L23: · 인터페이스 설계서 | Q23: 완료 | R23: 수용 | S23: 수용 | T23: 46246
E24: INR-003-02-01 | F24: 증분 인덱싱 파이프라인으로 전달 | G24: 시스템은 수집 대상 게시판·카테고리·문서 유형을 관리자가 지정할 수 있어야 하며, 신규 게시물 등록 시 수집 대상 여부를 자동 판별하고 SFR에서 정의한 증분 인덱싱 파이프라인으로 전달하는 기능을 제공하여야 한다. | H24: RFP | J24: 게시판·카테고리·문서유형별 수집대상 자동판별 후 증분 인덱싱 파이프라인 전달 | Q24: 완료 | R24: 수용 | S24: 수용 | T24: 46246
E25: INR-003-03-01 | F25: 지식 저장소 인덱스 구조에 적재 | G25: 시스템은 수집된 문서에 대해 제도 구분·문서 유형·시행일자 등 메타데이터를 자동 또는 반자동으로 태깅하여 SFR에서 정의한 지식 저장소 인덱스 구조에 적재하여야 한다. | H25: RFP | J25: 제도구분·문서유형·시행일자 메타데이터 자동/반자동 태깅 및 지식 인덱스 적재 | Q25: 완료 | R25: 수용 | S25: 수용 | T25: 46246
A26: 인터페이스 요구사항 | B26: INR-004 | C26: STT 엔진 연동 인터페이스 | D26: 콜센터 상담 어시스턴트 및 회의록 생성 서비스를 위한 STT 엔진 실시간 연동 인터페이스 규격 정의 | E26: INR-004-01-01 | F26: [콜센터 STT 실시간 스트리밍 연동] | G26: 기존 콜센터 STT 엔진의 실시간 스트리밍 출력을 수신하기 위한 연동 인터페이스를 정의하여야 한다. | H26: RFP | J26: 기존 콜센터 STT 엔진의 실시간 스트리밍 출력을 수신하기 위한 연동 인터페이스를 정의 | L26: · 인터페이스 설계서 | Q26: 완료 | R26: 수용 | S26: 수용 | T26: 46246
E27: INR-004-01-02 | G27: 화자 구분 신호 규격(화자 ID, 발언 시작/종료 타임스탬프, 신뢰도 점수)을 정의하여야 한다. | H27: RFP | J27: 화자 구분 신호 규격(화자 ID, 발언 시작/종료 타임스탬프, 신뢰도 점수)을 정의 | Q27: 완료 | R27: 수용 | S27: 수용 | T27: 46246
E28: INR-004-01-03 | G28: STT 엔진과의 세션 관리(연결 설정, 유지, 종료) 프로토콜을 정의하여야 한다. | H28: RFP | J28: STT 엔진과의 세션 관리(연결 설정, 유지, 종료) 프로토콜을 정의 | Q28: 완료 | R28: 수용 | S28: 수용 | T28: 46246
E29: INR-004-02-01 | F29: [오류 처리 및 재시도 정책] | G29: 스트리밍 연결 끊김 시 자동 재연결 정책(재시도 횟수, 간격)을 정의하여야 한다. | H29: RFP | J29: 스트리밍 연결 끊김 시 자동 재연결 정책(재시도 횟수, 간격)을 정의 | Q29: 완료 | R29: 수용 | S29: 수용 | T29: 46246
E30: INR-004-02-02 | G30: 변환 실패 시 오류 코드 체계 및 대응 방안을 정의하여야 한다. | H30: RFP | J30: 변환 실패 시 오류 코드 체계 및 대응 방안을 정의 | Q30: 완료 | R30: 수용 | S30: 수용 | T30: 46246
A31: 인터페이스 요구사항 | B31: INR-005 | C31: 기간계 협약기관 정보 연동 인터페이스 | D31: 협약기관 서비스를 위한 기간계 협약기관 정보 일 배치 자동 수집 인터페이스 규격 정의 | E31: INR-005-01-01 | F31: [연동 방식 및 프로토콜] | G31: - 기간계 협약기관 정보 수집을 위한 연동 방식을 정의하여야 한다. · DB 직접 조회, API 연동 | H31: RFP | J31: 기간계 협약기관 정보 수집을 위한 연동 방식을 정의·DB 직접 조회, API 연동 | L31: · 인터페이스 설계서 | Q31: 완료 | R31: 수용 | S31: 수용 | T31: 46246
E32: INR-005-01-02 | G32: 연동 방식의 최종 선정은 위원회와 협의하여 확정한다. | H32: RFP | J32: 협약기관 정보 연동 방식은 기간계 구조 검토 후 위원회 협의·확정 | Q32: 완료 | R32: 수용 | S32: 수용 | T32: 46246
E33: INR-005-02-01 | F33: [배치 수집 프로토콜] | G33: 배치 실행 주기: 일 1회 (기본값), 관리자 웹 UI에서 조정 가능 | H33: RFP | J33: 배치 실행 주기: 일 1회 (기본값), 관리자 웹 UI에서 조정 가능 | Q33: 완료 | R33: 수용 | S33: 수용 | T33: 46246
E34: INR-005-02-02 | G34: 배치 실행 시각: 업무 시간 외 (기본 02:00), 관리자 설정 가능 | H34: RFP | J34: 배치 실행 시각: 업무 시간 외 (기본 02:00), 관리자 설정 가능 | Q34: 완료 | R34: 수용 | S34: 수용 | T34: 46246
E35: INR-005-02-03 | G35: 수집 방식: 전체 교체 또는 변경분(신규/수정/삭제) 증분 수집 | H35: RFP | J35: 수집 방식: 전체 교체 또는 변경분(신규/수정/삭제) 증분 수집 | Q35: 완료 | R35: 수용 | S35: 수용 | T35: 46246
E36: INR-005-02-04 | G36: 배치 수행 결과 리포트(변경 건수, 성공/실패) 생성 규격을 정의하여야 한다. | H36: RFP | J36: 배치 수행 결과 리포트(변경 건수, 성공/실패) 생성 규격을 정의 | Q36: 완료 | R36: 수용 | S36: 수용 | T36: 46246
E37: INR-005-03-01 | F37: [연동 데이터 항목] | G37: - 수신 데이터 항목을 정의하여야 한다: · 필수: 기관명, 협약 유형, 협약 제도 구분, 협약 일자, 상태(유효/해지) · 선택: 담당자 성명, 담당자 연락처, 담당 업무 | H37: RFP | J37: 기관명·협약유형·제도구분·협약일자·상태와 담당자 정보를 연동 항목으로 정의 | Q37: 완료 | R37: 수용 | S37: 수용 | T37: 46246
E38: INR-005-03-02 | G38: 데이터 형식(문자열/날짜/코드), 코드 체계(협약 유형, 제도 구분)를 명시하여야 한다. | H38: RFP | J38: 데이터 형식(문자열/날짜/코드), 코드 체계(협약 유형, 제도 구분)를 명시 | Q38: 완료 | R38: 수용 | S38: 수용 | T38: 46246
E39: INR-005-04-01 | F39: [인증 및 보안] | G39: 인증 방식을 정의하여야 한다. | H39: RFP | J39: 인증 방식을 정의 | Q39: 완료 | R39: 수용 | S39: 수용 | T39: 46246
E40: INR-005-04-02 | G40: 폐쇄망 내부 통신 시에도 전송 구간 암호화 적용 여부를 명시하여야 한다. | H40: RFP | J40: 폐쇄망 내부 통신 시에도 전송 구간 암호화 적용 여부를 명시 | Q40: 완료 | R40: 수용 | S40: 수용 | T40: 46246
E41: INR-005-05-01 | F41: [오류 처리] | G41: 배치 오류 발생 시 기존 데이터 유지 정책 및 관리자 알림 규격을 정의하여야 한다. | H41: RFP | J41: 배치 오류 발생 시 기존 데이터 유지 정책 및 관리자 알림 규격을 정의 | Q41: 완료 | R41: 수용 | S41: 수용 | T41: 46246
...

Sheet 데이터
A1: 요구사항정의서-비기능
A2: 사업명 | D2: 신용회복위원회 통합 AI 플랫폼 구축 사업 | H2: 업무 구분 | K2: 데이터 요구사항 | P2: 작성자 | S2: 김현근
A3: 단계 | D3: 요구분석, 설계, 구현, 테스트, 전개 | H3: 작성일자 | K3: 2026.08.24 | P3: 버전 | S3: v.0.999
A5: 요구사항 분류 | B5: 요구사항 고유번호 | C5: 요구사항 명 | D5: 정의 | E5: 상세요구사항ID | F5: 상세요구사항명 | G5: 상세요구사항 설명 | H5: 요구사항 출처 | I5: 담당 수행사 | J5: 제약사항 및 처리(수행)방안 | K5: 위원회 검토 의견(26.8.12.) | L5: 산출정보(RFP 기준) | M5: 산출물(방법론 테일러링 결과서) | N5: 요구사항 상태 | O5: 중요도 | P5: 담당자 | Q5: 완료여부 | R5: 수행사 수용 여부 | S5: 위원회 수용 여부 | T5: 비고(변경처리내역 등)
A6: 데이터 요구사항 | B6: DAR-001 | C6: 수집 대상 데이터 및 메타데이터 정의 | D6: 수집 데이터 범위 및 메타데이터 기준 정의 | E6: DAR-001-01-01 | F6: [수집 대상 데이터 정의] | G6: 내부망 수집 대상: 업무포털 게시자료, 기간계 연동 정보 등 문서의 상세 데이터 목록을 정의하여야 한다. | H6: RFP | I6: 제논 | J6: 내부망 수집 대상: 업무포털 게시자료, 기간계 연동 정보 등 문서의 데이터 목록을 정의 | L6: · 수집 데이터 목록 정의서 · 메타데이터 표준 관리항목 정의서 | Q6: 완료 | R6: 수용 | S6: 수용 | T6: 46246
E7: DAR-001-01-02 | G7: 외부망 수집 대상: 공공 API 연동 데이터, 관리자 수기 반입 외부 문서 등의 상세 데이터 목록을 정의하여야 한다. | H7: RFP | I7: 제논 | J7: 외부망 수집 대상: 공공 API 연동 데이터, 관리자 수기 반입 외부 문서 등의 데이터 목록을 정의 | Q7: 완료 | R7: 수용 | S7: 수용 | T7: 46246
E8: DAR-001-01-03 | G8: 각 수집 대상 데이터별 분류 체계, 보안등급, 수집 우선순위를 정의 상세 하여야 한다. | H8: RFP | I8: 제논 | J8: 수집대상별 분류체계·보안등급·수집 우선순위 정의 | Q8: 완료 | R8: 수용 | S8: 수용 | T8: 46246
E9: DAR-001-02-01 | F9: [메타데이터 정의] | G9: 문서 수준 및 청크 단위 메타데이터 항목을 정의하고, 상호 관계를 명시하여야 한다. | H9: RFP | I9: 제논 | J9: 문서 수준 및 청크 단위 메타데이터 항목을 정의하고, 상호 관계를 명시 | Q9: 완료 | R9: 수용 | S9: 수용 | T9: 46246
E10: DAR-001-02-02 | G10: 시행일·개정일 등 시계열 정보에 대한 관리 기준 및 시점별 적용 우선순위를 정의하여야 한다. | H10: RFP | I10: 제논 | J10: 시행일·개정일 등 시계열 정보에 대한 관리 기준 및 시점별 적용 우선순위를 정의 | Q10: 완료 | R10: 수용 | S10: 수용 | T10: 46246
E11: DAR-001-02-03 | G11: RAG 검색 시 필터링 및 가중치 부여에 활용할 항목을 식별하여야 한다. | H11: RFP | I11: 제논 | J11: RAG 검색 시 필터링 및 가중치 부여에 활용할 항목을 식별 | Q11: 완료 | R11: 수용 | S11: 수용 | T11: 46246
A12: 데이터 요구사항 | B12: DAR-002 | C12: 이력·로그·설정 변경 데이터 관리 정책 | D12: 이력·로그 데이터 관리 및 통제 기준 정의 | E12: DAR-002-01-01 | F12: [관리 대상 이력·로그 정의] | G12: 파이프라인 실행 이력(수집·파싱·임베딩 등), 질의·응답 처리 로그, 설정·콘텐츠 변경 이력 등 관리 대상 데이터의 범위를 정의하여야 한다. | H12: RFP | I12: 제논 | J12: 수집·파싱·임베딩·질의응답·설정변경 이력의 관리대상 범위 정의 | L12: · 데이터 관리 정책 정의서 | Q12: 완료 | R12: 수용 | S12: 수용 | T12: 46246
E13: DAR-002-02-01 | F13: [관리 정책] | G13: 이력·로그 데이터의 보존 기간, 저장 방식, 접근 권한 등 관리 기준을 정의하여야 한다. | H13: RFP | I13: 제논 | J13: 이력·로그 데이터의 보존 기간, 저장 방식, 접근 권한 등 관리 기준을 정의 | Q13: 완료 | R13: 수용 | S13: 수용 | T13: 46246
E14: DAR-002-02-02 | G14: 개인정보 및 민감정보는 관련 법령에 따라 마스킹 및 접근통제를 적용하여야 한다. | H14: RFP | I14: 제논 | J14: 개인정보 및 민감정보는 관련 법령에 따라 마스킹 및 접근통제를 적용 | Q14: 완료 | R14: 수용 | S14: 수용 | T14: 46246
E15: DAR-002-02-03 | G15: 세부 로그 항목 및 저장 구조는 사업자가 제안하며 기술협상을 통해 확정한다. | H15: RFP | I15: 제논 | J15: 세부 로그 항목 및 저장 구조는 사업자가 제안하며 기술협상을 통해 협의·확정 | Q15: 완료 | R15: 수용 | S15: 수용 | T15: 46246
A16: 데이터 요구사항 | B16: DAR-003 | C16: 사용자 활동 데이터 관리 정책 | D16: 사용자 데이터 수집·보존·활용 기준 정의 | E16: DAR-003-01-01 | F16: [사용자 활동 데이터 관리] | G16: 사용자 질의, 응답, 피드백 등 활동 데이터에 대한 수집·보존·활용 기준을 정의하여야 한다. | H16: RFP | I16: 제논 | J16: 사용자 질의, 응답, 피드백 등 활동 데이터에 대한 수집·보존·활용 기준을 정의 | L16: · 데이터 관리 정책 정의서 | Q16: 완료 | R16: 수용 | S16: 수용 | T16: 46246
E17: DAR-003-01-02 | G17: Ground Truth 데이터 구축 및 관리 방안을 정의하여야 한다. | H17: RFP | I17: 제논 | J17: Ground Truth 데이터 구축 및 관리 방안을 정의 | Q17: 완료 | R17: 수용 | S17: 수용 | T17: 46246
E18: DAR-003-01-03 | G18: 보존 기간, 활용 범위, 접근 권한 등을 정의하고, 개인정보 보호는 SER 기준을 따른다. | H18: RFP | I18: 제논 | J18: 보존 기간, 활용 범위, 접근 권한 등을 정의하고, 개인정보 보호는 SER 기준을 준수 | Q18: 완료 | R18: 수용 | S18: 수용 | T18: 46246
E19: DAR-003-01-04 | G19: 세부 관리 기준 및 활용 방식은 사업자가 제안하며 기술협상을 통해 확정한다. | H19: RFP | I19: 제논 | J19: 세부 관리 기준 및 활용 방식은 사업자가 제안하며 기술협상을 통해 협의·확정 | Q19: 완료 | R19: 수용 | S19: 수용 | T19: 46246
A20: 데이터 요구사항 | B20: DAR-004 | C20: 데이터 표준 수립 및 품질 관리 | D20: 데이터 표준·품질·구조 관리 기준 정의 | E20: DAR-004-01-01 | F20: [데이터 표준 수립] | G20: 데이터 표준(용어, 코드, 도메인 등)을 정의하고 관리 방안을 수립하여야 한다. | H20: RFP | I20: 제논 | J20: 데이터 표준(용어, 코드, 도메인 등)을 정의·관리 방안을 수립 | L20: · 데이터 표준 사전 · 데이터베이스 설계서 (ERD 포함) · 데이터 품질 검증 결과서 | Q20: 완료 | R20: 수용 | S20: 수용 | T20: 46246
E21: DAR-004-01-02 | G21: 행정안전부 공공데이터베이스 표준화 기준 및 위원회 내부 기준을 준 수하여야 한다. | H21: RFP | I21: 제논 | J21: 행정안전부 공공DB 표준화 기준 및 위원회 내부 표준 준수 | Q21: 완료 | R21: 수용 | S21: 수용 | T21: 46246
E22: DAR-004-02-01 | F22: [데이터 구조 설계 및 품질 관리] | G22: 데이터 구조(스키마) 설계 및 변경 이력 관리 기준을 정의하여야 한다. | H22: RFP | I22: 제논 | J22: 데이터 구조(스키마) 설계 및 변경 이력 관리 기준을 정의 | Q22: 완료 | R22: 수용 | S22: 수용 | T22: 46246
E23: DAR-004-02-02 | G23: 데이터 값의 정확성·완전성·일관성 확보를 위한 검증 기준 및 품질 관리 지표를 정의하여야 한다. | H23: RFP | I23: 제논 | J23: 데이터 값의 정확성·완전성·일관성 확보를 위한 검증 기준 및 품질 관리 지표를 정의 | Q23: 완료 | R23: 수용 | S23: 수용 | T23: 46246
E24: DAR-004-02-03 | G24: 메타데이터의 최신성 유지 방안 및 원천 데이터 변경 시 반영 체계를 포함하여야 한다. | H24: RFP | I24: 제논 | J24: 메타데이터의 최신성 유지 방안 및 원천 데이터 변경 시 반영 체계를 포함 | Q24: 완료 | R24: 수용 | S24: 수용 | T24: 46246
E25: DAR-004-03-01 | F25: [공통 기준] | G25: 관련 법령, 행정안전부 표준 및 내부 규정을 준수하여야 한다. | H25: RFP | I25: 제논 | J25: 관련 법령, 행정안전부 표준 및 내부 규정을 준수 | Q25: 완료 | R25: 수용 | S25: 수용 | T25: 46246
E26: DAR-004-03-02 | G26: 세부 기준 및 관리 수준은 사업자가 제안하며 기술협상을 통해 확정한다. | H26: RFP | I26: 제논 | J26: 세부 기준 및 관리 수준은 사업자가 제안하며 기술협상을 통해 협의·확정 | Q26: 완료 | R26: 수용 | S26: 수용 | T26: 46246
E27: DAR-004-03-03 | G27: 정의된 기준은 위원회의 검토 및 승인 절차를 거쳐 확정되어야 한다. | H27: RFP | I27: 제논 | J27: 정의된 기준은 위원회의 검토 및 승인 절차를 거쳐 확정 | Q27: 완료 | R27: 수용 | S27: 수용 | T27: 46246
A28: 데이터 요구사항 | B28: DAR-005 | C28: 차기 변제금 납입 및 소액 대출 연체 등 예측 모델 구축 시 input 데이터 처리 | D28: 차기 변제금 납입 및 소액 대출 연체 등 예측 모델 구축 시 input 데이터 처리 | E28: DAR-005-01-01 | F28: 해당 모델 구축 시 input 데이터 추출 등은 본 사업 사업자에서 대응 必. 단, 대상 및 조건 등은 주관부서와 사전 협의 필요 | G28: 해당 모델 구축 시 input 데이터 추출 등은 본 사업 사업자에서 대응 必. 단, 대상 및 조건 등은 주관부서와 사전 협의 필요 | H28: 기술협상서 | I28: PWC | J28: - 해당 모델 구축 시 input 데이터 추출 등은 본 사업 사업자에서 대응(단, DB접속 및 메타접속 권한 부여 필요) - 대상 및 조건 등은 주관부서와 협의하여 수행 (주관부서와 협의 기준은 위원회의 요구사항을 우선적으로 수용하는 것을 원칙으로 하며, 착수 후 분석/설계 기간 내에 기간계 API 연동 규격서 및 데이터 처리 방안 설계서를 제출하여 위원회의 최종 승인을 득해야 함) | Q28: 완료 | R28: 수용 | S28: 수용 | T28: 46246

Sheet 테스트
A1: 요구사항정의서-비기능
A2: 사업명 | D2: 신용회복위원회 통합 AI 플랫폼 구축 사업 | H2: 업무 구분 | K2: 테스트 요구사항 | P2: 작성자 | S2: 김현근
A3: 단계 | D3: 요구분석, 설계, 구현, 테스트, 전개 | H3: 작성일자 | K3: 2026.08.24 | P3: 버전 | S3: v.0.999
A5: 요구사항 분류 | B5: 요구사항 고유번호 | C5: 요구사항 명 | D5: 정의 | E5: 상세요구사항ID | F5: 상세요구사항명 | G5: 상세요구사항 설명 | H5: 요구사항 출처 | I5: 담당 수행사 | J5: 제약사항 및 처리(수행)방안 | K5: 위원회 검토 의견(26.8.12.) | L5: 산출정보(RFP 기준) | M5: 산출물(방법론 테일러링 결과서) | N5: 요구사항 상태 | O5: 중요도 | P5: 담당자 | Q5: 완료여부 | R5: 수행사 수용 여부 | S5: 위원회 수용 여부 | T5: 비고(변경처리내역 등)
A6: 테스트 요구사항 | B6: TER-001 | C6: 테스트 전략 및 계획 수립 | D6: 사업 목표 달성을 위한 테스트 전략·계획의 수립 및 관리 | E6: TER-001-01-01 | F6: [테스트 계획 수립] | G6: 사업자는 단위·통합·시스템·인수 테스트 등 단계별 테스트 전략을 수립하고, 테스트 계획서를 작성하여 위원회의 승인을 득하여야 한다. | H6: RFP | I6: 제논, 위고 | J6: 단위·통합·시스템·인수 테스트 전략·계획 수립 및 위원회 승인 획득 | L6: · 테스트 계획서 (단계별 범위•일정•절차 포함) · 테스트 시나리오 및 테스트 케이스 | Q6: 완료 | R6: 수용 | S6: 수용 | T6: 46246
E7: TER-001-01-02 | G7: 테스트 계획서에는 테스트 범위, 대상, 수행 방법, 일정, 환경 구성 방안을 포함하여야 한다. | H7: RFP | I7: 제논, 위고 | J7: 테스트 계획서에는 테스트 범위, 대상, 수행 방법, 일정, 환경 구성 방안을 포함 | L7: 테스트 시나리오 및 테스트 케이스 | Q7: 완료 | R7: 수용 | S7: 수용 | T7: 46246
A8: 테스트 요구사항 | B8: TER-002 | C8: 단위·통합·시스템 테스트 수행 | D8: 개발 단계별 테스트의 체계적 수행 및 결함 관리 | E8: TER-002-01-01 | F8: [단계별 테스트 수행] | G8: 사업자는 요구사항을 기반으로 테스트 케이스를 작성하고, 단위·통합·시스템 테스트를 수행하여야 한다. | H8: RFP | I8: 제논, 위고 | J8: 요구사항 기반 테스트케이스 작성 및 단위·통합·시스템 테스트 수행 | L8: · 단위•통합•시스템 테스트 결과서 · 결함 시정 조치 내역 | Q8: 완료 | R8: 수용 | S8: 수용 | T8: 46246
E9: TER-002-01-02 | G9: 통합 테스트는 시스템 간 인터페이스 정합성 및 데이터 흐름을 검증하고, 시스템 테스트는 기능·성능 요구사항 충족 여부를 위원회 참여 하에 검증하여야 한다. | H9: RFP | I9: 제논, 위고 | J9: 통합테스트로 I/F·데이터 흐름, 시스템테스트로 기능·성능 충족 여부를 위원회 참여로 검증 | Q9: 완료 | R9: 수용 | S9: 수용 | T9: 46246
E10: TER-002-01-03 | G10: 결함 발견 시 원인 분석 및 시정 조치를 완료할 때까지 반복 테스트를 수행하여야 한다. | H10: RFP | I10: 제논, 위고 | J10: 결함 발견 시 원인 분석 및 시정 조치를 완료할 때까지 반복 테스트를 수행 | Q10: 완료 | R10: 수용 | S10: 수용 | T10: 46246
E11: TER-002-01-04 | G11: 보안 취약점 정적 분석은 SER 기준을 따른다. | H11: RFP | I11: 제논, 위고 | J11: 보안 취약점 정적 분석은 SER 기준을 준수 | Q11: 완료 | R11: 수용 | S11: 수용 | T11: 46246
A12: 테스트 요구사항 | B12: TER-003 | C12: 생성형 AI 응답 품질 및 RAG 파이프라인 검증 | D12: RAG 기반 검색 정확도, 생성형 AI 응답 품질 및 RAG 파이프라인 전 단계에 대한 검증 | E12: TER-003-01-01 | F12: [AI 응답 품질 검증] | G12: 사업자는 RAG 파이프라인의 검색 정확도(재현율·정밀도)와 생성 응답품질(정확성·관련성·환각 발생률)을 검증하는 테스트를 수행하여야 한다. | H12: RFP | I12: 제논, 위고 | J12: RAG 파이프라인의 검색 정확도(재현율·정밀도)와 생성 응답품질(정확성·관련성·환각 발생률)을 검증하는 테스트를 수행 | L12: · AI 응답 품질 평가 결과서 · RAG 파이프라인 검증 결과서 | Q12: 완료 | R12: 수용 | S12: 수용 | T12: 46246
E13: TER-003-01-02 | G13: 정량적 합격 기준은 PER에 정의된 기준을 따르며, 구체적 테스트 시나리오 및 평가 데이터셋 규모는 기술협상 시 위원회와 협의하여 확정한다. | H13: RFP | I13: 제논, 위고 | J13: PER 정량기준 적용, 테스트 시나리오·평가셋 규모는 별도 협의·확정 | Q13: 완료 | R13: 수용 | S13: 수용 | T13: 46246
E14: TER-003-02-01 | F14: [RAG 파이프라인 검증] | G14: 사업자는 청크 데이터 품질 (표 깨짐, 텍스트 누락, 메타데이터 불일치 등)을 검증하여야 한다. | H14: RFP | I14: 제논, 위고 | J14: 청크 데이터 품질 (표 깨짐, 텍스트 누락, 메타데이터 불일치 등)을 검증 | Q14: 완료 | R14: 수용 | S14: 수용 | T14: 46246
E15: TER-003-02-02 | G15: SFR에서 정의한 검색 프리셋, 동의어 확장, 배치 전략 등 기능별 검색 품질 적합성을 검증하여야 한다. | H15: RFP | I15: 제논, 위고 | J15: SFR에서 정의한 검색 프리셋, 동의어 확장, 배치 전략 등 기능별 검색 품질 적합성을 검증 | Q15: 완료 | R15: 수용 | S15: 수용 | T15: 46246
E16: TER-003-02-03 | G16: 허용 오류율 기준 및 세부 검증 방법은 기술협상을 통해 확정한다. | H16: RFP | I16: 제논, 위고 | J16: 허용 오류율 기준 및 세부 검증 방법은 기술협상을 통해 협의·확정 | Q16: 완료 | R16: 수용 | S16: 수용 | T16: 46246
A17: 테스트 요구사항 | B17: TER-004 | C17: 인수 테스트 및 시범운영 | D17: 최종 인수 검증 및 서비스 개시 전 시범운영 수행 | E17: TER-004-01-01 | F17: [인수 테스트] | G17: 인수 테스트는 위원회가 주관하고 사업자가 지원하는 체계로 수행 하여야 한다. | H17: RFP | I17: 제논 | J17: 인수 테스트는 위원회가 주관하고 사업자가 지원하는 체계로 수행 | L17: · 인수 테스트 결과서 · 시범운영 결과 보고서 | Q17: 완료 | R17: 수용 | S17: 수용 | T17: 46246
E18: TER-004-01-02 | G18: 실 업무 담당자가 참여하는 사용자 수용 테스트(UAT)를 포함하며, 업무 시나리오 기반 테스트 결과를 제출하여야 한다. | H18: RFP | I18: 제논 | J18: 실 업무 담당자가 참여하는 사용자 수용 테스트(UAT)를 포함하며, 업무 시나리오 기반 테스트 결과를 제출 | Q18: 완료 | R18: 수용 | S18: 수용 | T18: 46246
E19: TER-004-01-03 | G19: 부적합 사항 발견 시 원인과 시정 조치 계획을 제출하고 재시험을 상세 통해 해결 여부를 확인하여야 한다. | H19: RFP | I19: 제논 | J19: 부적합 사항 발견 시 원인과 시정 조치 계획을 제출·재시험을 통해 해결 여부를 확인 | Q19: 완료 | R19: 수용 | S19: 수용 | T19: 46246
E20: TER-004-02-01 | F20: [시범운영] | G20: 시스템 개발 완료 후 최소 30일 이상의 시범운영을 수행하고, 그 결과를 보고하여야 한다. | H20: RFP | I20: 제논 | J20: 시스템 개발 완료 후 최소 30일 이상의 시범운영을 수행하고, 그 결과를 보고 | Q20: 완료 | R20: 수용 | S20: 수용 | T20: 46246
E21: TER-004-02-02 | G21: 시범운영 기간 중 성능 모니터링을 실시하고, 발견된 문제점을 보완하여야 한다. | H21: RFP | I21: 제논 | J21: 시범운영 기간 중 성능 모니터링을 실시하고, 발견된 문제점을 보완 | Q21: 완료 | R21: 수용 | S21: 수용 | T21: 46246
E22: TER-004-02-03 | G22: 시범운영 기간은 위원회와 협의하여 조정할 수 있다. | H22: RFP | I22: 제논 | J22: 시범운영 기간은 위원회 협의 후 조정 가능 | Q22: 완료 | R22: 수용 | S22: 수용 | T22: 46246
A23: 테스트 요구사항 | B23: TER-005 | C23: 예측 모델 초기 성능 검증 | D23: 예측 모델 초기 성능 검증 | E23: TER-005-01-01 | F23: [성능 지표 검증] | G23: 사업자는 모델 학습 완료 후 검증용 데이터를 활용하여 예측 정확도를 수치로 산출하고 위원회에 보고하여야 한다. | H23: RFP | I23: PwC | J23: 모델 학습 완료 후 검증용 데이터를 활용하여 예측 정확도를 수치로 산출하고 위원회에 보고 | L23: · 예측 모델 성능 검증 결과서 | Q23: 완료 | R23: 수용 | S23: 수용 | T23: 46246
E24: TER-005-01-02 | G24: 정확도 측정 방식 및 합격 기준은 기술협상 시 위원회와 협의하여 확정한다. 다만, 사업자는 제안서에 달성 목표값을 명시하여야 한다. | H24: RFP | I24: PwC | J24: 예측모델 정확도 산식·합격기준은 별도 협의·확정하고 제안 목표값 명시 | Q24: 완료 | R24: 수용 | S24: 수용 | T24: 46246
E25: TER-005-02-01 | F25: [현업 확인 검증] | G25: 사업자는 모델이 산출한 이행자별 위험등급 분류 결과를 실무 담당자가 직접 확인하고, 실제 업무에 활용 가능한 수준인지를 검토하는 현업 확인 절차를 수행하고 결과를 제출하여야 한다. | H25: RFP | I25: PwC | J25: 위험등급 결과를 현업이 직접 확인해 실무 활용 가능성을 검증하고 결과 제출 | Q25: 완료 | R25: 수용 | S25: 수용 | T25: 46246

Sheet 보안
A1: 요구사항정의서-비기능
A2: 사업명 | D2: 신용회복위원회 통합 AI 플랫폼 구축 사업 | H2: 업무 구분 | K2: 보안 요구사항 | P2: 작성자 | S2: 김현근
A3: 단계 | D3: 요구분석, 설계, 구현, 테스트, 전개 | H3: 작성일자 | K3: 2026.08.24 | P3: 버전 | S3: v.0.999
A5: 요구사항 분류 | B5: 요구사항 고유번호 | C5: 요구사항 명 | D5: 정의 | E5: 상세요구사항ID | F5: 상세요구사항명 | G5: 상세요구사항 설명 | H5: 요구사항 출처 | I5: 담당 수행사 | J5: 제약사항 및 처리(수행)방안 | K5: 위원회 검토 의견(26.8.12.) | L5: 산출정보(RFP 기준) | M5: 산출물(방법론 테일러링 결과서) | N5: 요구사항 상태 | O5: 중요도 | P5: 담당자 | Q5: 완료여부 | R5: 수행사 수용 여부 | S5: 위원회 수용 여부 | T5: 비고(변경처리내역 등)
A6: 보안 요구사항 | B6: SER-001 | C6: 문서 접근 권한 통제 | D6: RBAC 기반 문서·버전별 접근 권한 통제, 수집 데이터 보안등급 관리 및 외부 데이터 반입 무해화·검증 체계 | E6: SER-001-01-01 | F6: [역할 기반 접근 통제(RBAC)] | G6: 시스템은 사용자의 직급, 직책, 부서, 등급에 따라 문서별, 버전별(현행/과거 /예정) 접근 권한을 제어하여야 한다. 권한 설정은 개별 사용자 단위 또는 그룹(부서/직급) 단위로 가능하여야 한다. | H6: RFP | I6: 제논 | J6: 직급·직책·부서·등급별 문서·버전 접근권한을 사용자/그룹 단위로 제어 | L6: · 보안 아키텍처 정의서 | Q6: 완료 | R6: 수용 | S6: 수용 | T6: 46246
E7: SER-001-01-02 | G7: 관리자 권한 분리 원칙을 적용하여 플랫폼 관리자와 권한을 부여받은 사용 자의 접근 범위를 구분하여야 한다. | H7: RFP | I7: 제논 | J7: 플랫폼 관리자와 권한 부여 사용자 간 접근범위 분리 | Q7: 완료 | R7: 수용 | S7: 수용 | T7: 46246
E8: SER-001-01-03 | G8: AI Agent 단위별로 사용자부서그룹별 접근 시 차단 및 로그 기록을 적용하여야 한다. | H8: RFP | I8: 제논 | J8: Agent별 사용자·부서·그룹 접근통제 및 차단 로그 기록 | Q8: 완료 | R8: 수용 | S8: 수용 | T8: 46246
E9: SER-001-01-04 | G9: AI 서비스(RAG 검색·인용) 시점의 접근 권한 적용은 본 항목에서 정의한 RBAC 정책을 기반으로 하되, 런타임 적용 기능의 구현은 SFR-011에서 정의한다. | H9: RFP | I9: 제논 | J9: SER-001 RBAC 정책을 SFR-011 RAG 검색·인용 런타임 접근통제에 연계 | Q9: 완료 | R9: 수용 | S9: 수용 | T9: 46246
